File: exp_dat/texture/MV8_740_0%.UXD
; C:\DIFFDAT1\GIFT\MDL\Seawoong Lee\20140217\MV8_740_0%_R.raw(Diffrac Plus V1.01 file) converted by XCH V1.0
_FILEVERSION=2
_SITE='Korea'
_USER='Admin'
_SAMPLE_CHANGER_CODE=0
_ATTACHMENTS_CODE=0
_GONIOMETER_RADIUS=300.000000
_FIXED_DIVSLIT=1.000000
_FIXED_SAMPLESLIT=0.000000
_FIXED_DETSLIT=0.100000
_MONOCHROMATOR=0
; None
_THIN_FILM='N'
_BETA_FILTER='Y'
_FIXED_ANTISLIT=0.600000
_ANALYZER_CODE=0
; None
_DATEMEASURED='18-Feb-2014 16:36:00'
_WL_UNIT='A'
_WL1=1.788970
_WL2=1.792850
_WL3=1.620790
_WLRATIO=0.500000
_ANODE='Co'
; (Data for Range number 1)
_DRIVE='PHI'
_STEPTIME=2.000000
_STEPSIZE=5.000000
_STEPMODE='C'
_START=0.000000
_THETA=29.850000
_2THETA=59.700001
_KHI=0.000000
_PHI=0.000000
_X=0.000000
_Y=0.000000
_Z=0.000000
_DIVERGENCE=3.000000
_ANTISCATTER=3.000000
_DETECTOR=1
; S.C.
_HV=687.000000
_GAIN=80.000000
_LLD=0.690000
_ULD=1.866000
_DETECTORSLIT='unkn'
_AUX1=0.000000
_AUX2=0.000000
_AUX3=0.000000
_TIMESTARTED=15.000000
_TEMP_RATE=0.000000
_TEMP_DELAY=0.000000
_KV=35
_MA=40
_RANGE_WL=1.788970
_3DPLANE=0
_2THETACPS
   0.0000    2540.5
   5.0000    2417.0
  10.0000    2497.0
  15.0000    2479.0
  20.0000    2454.5
  25.0000    2499.5
  30.0000    2604.0
  35.0000    2563.5
  40.0000    2621.5
  45.0000    2680.0
  50.0000    2574.0
  55.0000    2612.0
  60.0000    2548.0
  65.0000    2567.0
  70.0000    2573.0
  75.0000    2536.0
  80.0000    2602.5
  85.0000    2595.0
  90.0000    2538.0
  95.0000    2561.0
 100.0000    2563.0
 105.0000    2594.5
 110.0000    2602.0
 115.0000    2582.5
 120.0000    2529.0
 125.0000    2507.5
 130.0000    2449.0
 135.0000    2337.5
 140.0000    2320.0
 145.0000    2239.5
 150.0000    2175.0
 155.0000    2111.5
 160.0000    2073.0
 165.0000    2101.5
 170.0000    1927.5
 175.0000    1916.0
 180.0000    1955.5
 185.0000    1970.0
 190.0000    1952.0
 195.0000    1906.5
 200.0000    1990.5
 205.0000    1968.5
 210.0000    1955.0
 215.0000    2053.0
 220.0000    2054.0
 225.0000    2147.5
 230.0000    2317.0
 235.0000    2337.0
 240.0000    2486.0
 245.0000    2492.5
 250.0000    2492.0
 255.0000    2506.0
 260.0000    2536.0
 265.0000    2497.0
 270.0000    2506.5
 275.0000    2490.5
 280.0000    2476.0
 285.0000    2558.0
 290.0000    2494.5
 295.0000    2557.5
 300.0000    2606.5
 305.0000    2555.0
 310.0000    2510.5
 315.0000    2583.0
 320.0000    2564.0
 325.0000    2586.5
 330.0000    2579.5
 335.0000    2538.0
 340.0000    2401.0
 345.0000    2499.5
 350.0000    2479.0
 355.0000    2505.0
; (Data for Range number 2)
_DRIVE='PHI'
_STEPTIME=2.000000
_STEPSIZE=5.000000
_STEPMODE='C'
_START=0.000000
_THETA=29.850000
_2THETA=59.700001
_KHI=5.000000
_PHI=0.000000
_X=0.000000
_Y=0.000000
_Z=0.000000
_DIVERGENCE=3.000000
_ANTISCATTER=3.000000
_DETECTOR=1
; S.C.
_HV=687.000000
_GAIN=80.000000
_LLD=0.690000
_ULD=1.866000
_DETECTORSLIT='unkn'
_AUX1=0.000000
_AUX2=0.000000
_AUX3=0.000000
_TIMESTARTED=220.000000
_TEMP_RATE=0.000000
_TEMP_DELAY=0.000000
_KV=35
_MA=40
_RANGE_WL=1.788970
_3DPLANE=0
_2THETACPS
   0.0000    2558.5
   5.0000    2495.0
  10.0000    2491.0
  15.0000    2570.5
  20.0000    2558.5
  25.0000    2514.5
  30.0000    2641.0
  35.0000    2519.5
  40.0000    2601.5
  45.0000    2635.0
  50.0000    2552.5
  55.0000    2626.5
  60.0000    2599.5
  65.0000    2532.5
  70.0000    2562.0
  75.0000    2574.0
  80.0000    2559.5
  85.0000    2558.5
  90.0000    2545.0
  95.0000    2552.5
 100.0000    2528.0
 105.0000    2604.5
 110.0000    2567.0
 115.0000    2550.0
 120.0000    2511.0
 125.0000    2448.0
 130.0000    2397.5
 135.0000    2342.5
 140.0000    2307.0
 145.0000    2280.5
 150.0000    2195.0
 155.0000    2085.0
 160.0000    2087.0
 165.0000    2072.5
 170.0000    2040.0
 175.0000    2028.0
 180.0000    1967.0
 185.0000    1970.0
 190.0000    1966.5
 195.0000    1945.0
 200.0000    1971.5
 205.0000    2001.0
 210.0000    2068.5
 215.0000    2095.0
 220.0000    2197.0
 225.0000    2276.0
 230.0000    2423.5
 235.0000    2421.5
 240.0000    2479.0
 245.0000    2526.0
 250.0000    2564.5
 255.0000    2450.0
 260.0000    2584.0
 265.0000    2514.0
 270.0000    2558.0
 275.0000    2598.5
 280.0000    2511.0
 285.0000    2519.5
 290.0000    2519.0
 295.0000    2524.5
 300.0000    2618.5
 305.0000    2541.5
 310.0000    2583.5
 315.0000    2603.0
 320.0000    2579.0
 325.0000    2604.0
 330.0000    2581.0
 335.0000    2552.5
 340.0000    2513.5
 345.0000    2559.5
 350.0000    2475.0
 355.0000    2508.5
; (Data for Range number 3)
_DRIVE='PHI'
_STEPTIME=2.000000
_STEPSIZE=5.000000
_STEPMODE='C'
_START=0.000000
_THETA=29.850000
_2THETA=59.700001
_KHI=10.000000
_PHI=0.000000
_X=0.000000
_Y=0.000000
_Z=0.000000
_DIVERGENCE=3.000000
_ANTISCATTER=3.000000
_DETECTOR=1
; S.C.
_HV=687.000000
_GAIN=80.000000
_LLD=0.690000
_ULD=1.866000
_DETECTORSLIT='unkn'
_AUX1=0.000000
_AUX2=0.000000
_AUX3=0.000000
_TIMESTARTED=425.000000
_TEMP_RATE=0.000000
_TEMP_DELAY=0.000000
_KV=35
_MA=40
_RANGE_WL=1.788970
_3DPLANE=0
_2THETACPS
   0.0000    2531.5
   5.0000    2588.5
  10.0000    2594.5
  15.0000    2582.5
  20.0000    2558.0
  25.0000    2582.0
  30.0000    2665.0
  35.0000    2680.0
  40.0000    2647.5
  45.0000    2624.5
  50.0000    2670.0
  55.0000    2613.0
  60.0000    2552.0
  65.0000    2654.5
  70.0000    2642.5
  75.0000    2707.0
  80.0000    2619.5
  85.0000    2606.0
  90.0000    2612.0
  95.0000    2637.5
 100.0000    2580.5
 105.0000    2570.5
 110.0000    2582.5
 115.0000    2567.5
 120.0000    2573.5
 125.0000    2452.5
 130.0000    2429.5
 135.0000    2319.5
 140.0000    2290.0
 145.0000    2259.0
 150.0000    2247.5
 155.0000    2176.0
 160.0000    2150.0
 165.0000    2093.5
 170.0000    2080.0
 175.0000    2042.5
 180.0000    2062.0
 185.0000    2072.0
 190.0000    2019.0
 195.0000    2028.0
 200.0000    2027.5
 205.0000    2089.0
 210.0000    2173.5
 215.0000    2169.5
 220.0000    2284.5
 225.0000    2381.0
 230.0000    2422.5
 235.0000    2473.5
 240.0000    2528.5
 245.0000    2632.5
 250.0000    2566.5
 255.0000    2483.5
 260.0000    2471.5
 265.0000    2574.5
 270.0000    2570.0
 275.0000    2597.0
 280.0000    2607.5
 285.0000    2613.5
 290.0000    2579.5
 295.0000    2590.0
 300.0000    2569.5
 305.0000    2595.5
 310.0000    2571.5
 315.0000    2669.5
 320.0000    2591.5
 325.0000    2623.0
 330.0000    2640.0
 335.0000    2524.0
 340.0000    2636.5
 345.0000    2542.5
 350.0000    2553.0
 355.0000    2511.5
; (Data for Range number 4)
_DRIVE='PHI'
_STEPTIME=2.000000
_STEPSIZE=5.000000
_STEPMODE='C'
_START=0.000000
_THETA=29.850000
_2THETA=59.700001
_KHI=15.000000
_PHI=0.000000
_X=0.000000
_Y=0.000000
_Z=0.000000
_DIVERGENCE=3.000000
_ANTISCATTER=3.000000
_DETECTOR=1
; S.C.
_HV=687.000000
_GAIN=80.000000
_LLD=0.690000
_ULD=1.866000
_DETECTORSLIT='unkn'
_AUX1=0.000000
_AUX2=0.000000
_AUX3=0.000000
_TIMESTARTED=629.000000
_TEMP_RATE=0.000000
_TEMP_DELAY=0.000000
_KV=35
_MA=40
_RANGE_WL=1.788970
_3DPLANE=0
_2THETACPS
   0.0000    2672.0
   5.0000    2678.0
  10.0000    2665.5
  15.0000    2663.0
  20.0000    2714.5
  25.0000    2710.0
  30.0000    2756.5
  35.0000    2714.0
  40.0000    2774.5
  45.0000    2673.5
  50.0000    2713.0
  55.0000    2685.0
  60.0000    2676.5
  65.0000    2621.5
  70.0000    2644.5
  75.0000    2623.0
  80.0000    2654.5
  85.0000    2633.0
  90.0000    2640.0
  95.0000    2635.5
 100.0000    2525.0
 105.0000    2680.0
 110.0000    2680.0
 115.0000    2636.0
 120.0000    2550.0
 125.0000    2481.5
 130.0000    2475.0
 135.0000    2380.5
 140.0000    2315.0
 145.0000    2360.0
 150.0000    2247.5
 155.0000    2237.5
 160.0000    2270.0
 165.0000    2169.0
 170.0000    2210.5
 175.0000    2161.0
 180.0000    2157.0
 185.0000    2133.0
 190.0000    2175.5
 195.0000    2147.5
 200.0000    2218.0
 205.0000    2186.0
 210.0000    2264.5
 215.0000    2268.0
 220.0000    2374.0
 225.0000    2478.5
 230.0000    2551.0
 235.0000    2612.5
 240.0000    2618.5
 245.0000    2602.5
 250.0000    2557.0
 255.0000    2584.5
 260.0000    2568.5
 265.0000    2623.5
 270.0000    2694.5
 275.0000    2619.0
 280.0000    2579.5
 285.0000    2619.0
 290.0000    2678.0
 295.0000    2633.5
 300.0000    2633.5
 305.0000    2681.0
 310.0000    2768.0
 315.0000    2735.5
 320.0000    2682.5
 325.0000    2692.5
 330.0000    2780.5
 335.0000    2726.0
 340.0000    2691.5
 345.0000    2707.0
 350.0000    2726.0
 355.0000    2693.5
; (Data for Range number 5)
_DRIVE='PHI'
_STEPTIME=2.000000
_STEPSIZE=5.000000
_STEPMODE='C'
_START=0.000000
_THETA=29.850000
_2THETA=59.700001
_KHI=20.000000
_PHI=0.000000
_X=0.000000
_Y=0.000000
_Z=0.000000
_DIVERGENCE=3.000000
_ANTISCATTER=3.000000
_DETECTOR=1
; S.C.
_HV=687.000000
_GAIN=80.000000
_LLD=0.690000
_ULD=1.866000
_DETECTORSLIT='unkn'
_AUX1=0.000000
_AUX2=0.000000
_AUX3=0.000000
_TIMESTARTED=834.000000
_TEMP_RATE=0.000000
_TEMP_DELAY=0.000000
_KV=35
_MA=40
_RANGE_WL=1.788970
_3DPLANE=0
_2THETACPS
   0.0000    2963.5
   5.0000    2981.0
  10.0000    2956.5
  15.0000    2950.5
  20.0000    2895.5
  25.0000    2936.5
  30.0000    2896.5
  35.0000    2880.0
  40.0000    2897.0
  45.0000    2762.0
  50.0000    2841.0
  55.0000    2783.0
  60.0000    2743.5
  65.0000    2719.5
  70.0000    2747.0
  75.0000    2728.0
  80.0000    2745.0
  85.0000    2688.0
  90.0000    2622.0
  95.0000    2769.5
 100.0000    2685.0
 105.0000    2734.5
 110.0000    2707.0
 115.0000    2610.0
 120.0000    2657.5
 125.0000    2651.5
 130.0000    2570.5
 135.0000    2529.0
 140.0000    2519.5
 145.0000    2554.5
 150.0000    2522.0
 155.0000    2439.5
 160.0000    2471.5
 165.0000    2450.0
 170.0000    2459.0
 175.0000    2396.5
 180.0000    2373.5
 185.0000    2362.5
 190.0000    2356.0
 195.0000    2388.0
 200.0000    2397.0
 205.0000    2363.5
 210.0000    2404.5
 215.0000    2490.5
 220.0000    2531.5
 225.0000    2591.0
 230.0000    2680.0
 235.0000    2683.5
 240.0000    2618.0
 245.0000    2697.5
 250.0000    2745.0
 255.0000    2735.0
 260.0000    2702.5
 265.0000    2706.0
 270.0000    2605.0
 275.0000    2703.0
 280.0000    2750.5
 285.0000    2722.0
 290.0000    2799.5
 295.0000    2808.0
 300.0000    2772.5
 305.0000    2818.0
 310.0000    2911.0
 315.0000    2933.0
 320.0000    2939.5
 325.0000    2964.5
 330.0000    2958.5
 335.0000    2927.5
 340.0000    2899.5
 345.0000    2973.5
 350.0000    2979.5
 355.0000    2982.5
; (Data for Range number 6)
_DRIVE='PHI'
_STEPTIME=2.000000
_STEPSIZE=5.000000
_STEPMODE='C'
_START=0.000000
_THETA=29.850000
_2THETA=59.700001
_KHI=25.000000
_PHI=0.000000
_X=0.000000
_Y=0.000000
_Z=0.000000
_DIVERGENCE=3.000000
_ANTISCATTER=3.000000
_DETECTOR=1
; S.C.
_HV=687.000000
_GAIN=80.000000
_LLD=0.690000
_ULD=1.866000
_DETECTORSLIT='unkn'
_AUX1=0.000000
_AUX2=0.000000
_AUX3=0.000000
_TIMESTARTED=1039.000000
_TEMP_RATE=0.000000
_TEMP_DELAY=0.000000
_KV=35
_MA=40
_RANGE_WL=1.788970
_3DPLANE=0
_2THETACPS
   0.0000    3348.5
   5.0000    3269.5
  10.0000    3273.0
  15.0000    3273.0
  20.0000    3226.0
  25.0000    3229.5
  30.0000    3204.5
  35.0000    3090.5
  40.0000    3065.0
  45.0000    3088.0
  50.0000    2937.0
  55.0000    2954.5
  60.0000    2823.0
  65.0000    2834.0
  70.0000    2809.5
  75.0000    2848.0
  80.0000    2815.0
  85.0000    2704.5
  90.0000    2827.0
  95.0000    2800.5
 100.0000    2827.5
 105.0000    2727.0
 110.0000    2787.5
 115.0000    2754.0
 120.0000    2786.5
 125.0000    2694.0
 130.0000    2738.0
 135.0000    2740.0
 140.0000    2752.0
 145.0000    2703.5
 150.0000    2717.0
 155.0000    2705.5
 160.0000    2804.0
 165.0000    2751.5
 170.0000    2759.0
 175.0000    2730.5
 180.0000    2648.5
 185.0000    2677.5
 190.0000    2743.5
 195.0000    2656.0
 200.0000    2644.5
 205.0000    2718.0
 210.0000    2737.5
 215.0000    2718.0
 220.0000    2794.5
 225.0000    2774.0
 230.0000    2863.5
 235.0000    2801.0
 240.0000    2742.5
 245.0000    2789.5
 250.0000    2821.5
 255.0000    2758.5
 260.0000    2811.5
 265.0000    2797.5
 270.0000    2738.0
 275.0000    2764.0
 280.0000    2806.5
 285.0000    2873.5
 290.0000    2901.0
 295.0000    2910.0
 300.0000    3009.0
 305.0000    3065.5
 310.0000    3056.0
 315.0000    3259.5
 320.0000    3116.0
 325.0000    3139.5
 330.0000    3215.0
 335.0000    3279.5
 340.0000    3204.0
 345.0000    3248.0
 350.0000    3211.5
 355.0000    3306.5
; (Data for Range number 7)
_DRIVE='PHI'
_STEPTIME=2.000000
_STEPSIZE=5.000000
_STEPMODE='C'
_START=0.000000
_THETA=29.850000
_2THETA=59.700001
_KHI=30.000000
_PHI=0.000000
_X=0.000000
_Y=0.000000
_Z=0.000000
_DIVERGENCE=3.000000
_ANTISCATTER=3.000000
_DETECTOR=1
; S.C.
_HV=687.000000
_GAIN=80.000000
_LLD=0.690000
_ULD=1.866000
_DETECTORSLIT='unkn'
_AUX1=0.000000
_AUX2=0.000000
_AUX3=0.000000
_TIMESTARTED=1244.000000
_TEMP_RATE=0.000000
_TEMP_DELAY=0.000000
_KV=35
_MA=40
_RANGE_WL=1.788970
_3DPLANE=0
_2THETACPS
   0.0000    3320.0
   5.0000    3303.5
  10.0000    3358.5
  15.0000    3393.5
  20.0000    3399.5
  25.0000    3366.0
  30.0000    3388.5
  35.0000    3394.0
  40.0000    3301.5
  45.0000    3199.5
  50.0000    3132.5
  55.0000    3081.0
  60.0000    2997.0
  65.0000    3009.5
  70.0000    2940.0
  75.0000    2956.0
  80.0000    2765.5
  85.0000    2899.0
  90.0000    2919.0
  95.0000    2856.5
 100.0000    2840.0
 105.0000    2924.0
 110.0000    2883.5
 115.0000    2915.5
 120.0000    2864.0
 125.0000    2893.0
 130.0000    2889.5
 135.0000    2848.0
 140.0000    2859.0
 145.0000    2830.5
 150.0000    2831.0
 155.0000    2856.0
 160.0000    2809.5
 165.0000    2890.5
 170.0000    2831.5
 175.0000    2773.5
 180.0000    2815.0
 185.0000    2752.5
 190.0000    2782.0
 195.0000    2823.5
 200.0000    2873.0
 205.0000    2871.0
 210.0000    2903.0
 215.0000    3019.0
 220.0000    3000.0
 225.0000    3059.5
 230.0000    2993.5
 235.0000    3069.5
 240.0000    2958.0
 245.0000    2952.0
 250.0000    2905.0
 255.0000    2817.5
 260.0000    2837.0
 265.0000    2827.0
 270.0000    2887.0
 275.0000    2910.0
 280.0000    2910.5
 285.0000    2986.0
 290.0000    3002.5
 295.0000    3128.0
 300.0000    3168.0
 305.0000    3258.0
 310.0000    3280.0
 315.0000    3381.5
 320.0000    3341.0
 325.0000    3359.5
 330.0000    3321.0
 335.0000    3211.5
 340.0000    3253.0
 345.0000    3252.5
 350.0000    3245.5
 355.0000    3342.5
; (Data for Range number 8)
_DRIVE='PHI'
_STEPTIME=2.000000
_STEPSIZE=5.000000
_STEPMODE='C'
_START=0.000000
_THETA=29.850000
_2THETA=59.700001
_KHI=35.000000
_PHI=0.000000
_X=0.000000
_Y=0.000000
_Z=0.000000
_DIVERGENCE=3.000000
_ANTISCATTER=3.000000
_DETECTOR=1
; S.C.
_HV=687.000000
_GAIN=80.000000
_LLD=0.690000
_ULD=1.866000
_DETECTORSLIT='unkn'
_AUX1=0.000000
_AUX2=0.000000
_AUX3=0.000000
_TIMESTARTED=1448.000000
_TEMP_RATE=0.000000
_TEMP_DELAY=0.000000
_KV=35
_MA=40
_RANGE_WL=1.788970
_3DPLANE=0
_2THETACPS
   0.0000    3023.5
   5.0000    2967.0
  10.0000    3076.0
  15.0000    3207.5
  20.0000    3284.0
  25.0000    3311.0
  30.0000    3439.5
  35.0000    3516.0
  40.0000    3489.0
  45.0000    3422.0
  50.0000    3293.0
  55.0000    3225.0
  60.0000    3167.5
  65.0000    3136.0
  70.0000    3036.5
  75.0000    3034.5
  80.0000    2970.5
  85.0000    2990.0
  90.0000    2993.0
  95.0000    2909.5
 100.0000    2949.0
 105.0000    3004.5
 110.0000    3055.0
 115.0000    2921.0
 120.0000    2969.5
 125.0000    2982.0
 130.0000    2953.5
 135.0000    2854.0
 140.0000    2900.0
 145.0000    2773.5
 150.0000    2735.5
 155.0000    2671.5
 160.0000    2649.5
 165.0000    2599.5
 170.0000    2529.5
 175.0000    2491.5
 180.0000    2592.0
 185.0000    2550.0
 190.0000    2517.0
 195.0000    2664.0
 200.0000    2795.5
 205.0000    2805.0
 210.0000    2868.5
 215.0000    3054.5
 220.0000    3132.0
 225.0000    3187.0
 230.0000    3220.0
 235.0000    3189.5
 240.0000    3114.5
 245.0000    3003.5
 250.0000    2951.5
 255.0000    2955.5
 260.0000    2984.0
 265.0000    2899.5
 270.0000    2890.0
 275.0000    2962.5
 280.0000    3094.5
 285.0000    3111.0
 290.0000    3202.5
 295.0000    3260.0
 300.0000    3315.0
 305.0000    3338.5
 310.0000    3397.0
 315.0000    3334.0
 320.0000    3243.5
 325.0000    3166.5
 330.0000    3076.0
 335.0000    3073.5
 340.0000    3058.0
 345.0000    3002.0
 350.0000    2918.0
 355.0000    2928.5
; (Data for Range number 9)
_DRIVE='PHI'
_STEPTIME=2.000000
_STEPSIZE=5.000000
_STEPMODE='C'
_START=0.000000
_THETA=29.850000
_2THETA=59.700001
_KHI=40.000000
_PHI=0.000000
_X=0.000000
_Y=0.000000
_Z=0.000000
_DIVERGENCE=3.000000
_ANTISCATTER=3.000000
_DETECTOR=1
; S.C.
_HV=687.000000
_GAIN=80.000000
_LLD=0.690000
_ULD=1.866000
_DETECTORSLIT='unkn'
_AUX1=0.000000
_AUX2=0.000000
_AUX3=0.000000
_TIMESTARTED=1654.000000
_TEMP_RATE=0.000000
_TEMP_DELAY=0.000000
_KV=35
_MA=40
_RANGE_WL=1.788970
_3DPLANE=0
_2THETACPS
   0.0000    2608.5
   5.0000    2666.5
  10.0000    2735.0
  15.0000    2913.5
  20.0000    3020.5
  25.0000    3184.5
  30.0000    3315.0
  35.0000    3361.5
  40.0000    3412.0
  45.0000    3346.5
  50.0000    3346.0
  55.0000    3296.5
  60.0000    3190.5
  65.0000    3154.5
  70.0000    3115.0
  75.0000    3024.5
  80.0000    2957.0
  85.0000    2978.0
  90.0000    3037.0
  95.0000    3046.0
 100.0000    3076.5
 105.0000    3023.0
 110.0000    2977.5
 115.0000    2997.5
 120.0000    2987.0
 125.0000    2910.0
 130.0000    2896.0
 135.0000    2802.5
 140.0000    2727.5
 145.0000    2693.5
 150.0000    2471.5
 155.0000    2351.5
 160.0000    2345.5
 165.0000    2253.5
 170.0000    2198.0
 175.0000    2208.5
 180.0000    2234.0
 185.0000    2261.5
 190.0000    2360.5
 195.0000    2409.0
 200.0000    2500.0
 205.0000    2710.5
 210.0000    2836.0
 215.0000    2967.0
 220.0000    3067.0
 225.0000    3265.0
 230.0000    3243.5
 235.0000    3286.0
 240.0000    3194.5
 245.0000    3121.5
 250.0000    3079.0
 255.0000    3009.5
 260.0000    3009.0
 265.0000    2950.5
 270.0000    2966.5
 275.0000    3003.5
 280.0000    3069.5
 285.0000    3101.0
 290.0000    3169.5
 295.0000    3277.0
 300.0000    3319.0
 305.0000    3310.5
 310.0000    3320.0
 315.0000    3170.5
 320.0000    3014.0
 325.0000    2946.5
 330.0000    2781.0
 335.0000    2763.0
 340.0000    2626.5
 345.0000    2597.5
 350.0000    2580.5
 355.0000    2543.5
; (Data for Range number 10)
_DRIVE='PHI'
_STEPTIME=2.000000
_STEPSIZE=5.000000
_STEPMODE='C'
_START=0.000000
_THETA=29.850000
_2THETA=59.700001
_KHI=45.000000
_PHI=0.000000
_X=0.000000
_Y=0.000000
_Z=0.000000
_DIVERGENCE=3.000000
_ANTISCATTER=3.000000
_DETECTOR=1
; S.C.
_HV=687.000000
_GAIN=80.000000
_LLD=0.690000
_ULD=1.866000
_DETECTORSLIT='unkn'
_AUX1=0.000000
_AUX2=0.000000
_AUX3=0.000000
_TIMESTARTED=1859.000000
_TEMP_RATE=0.000000
_TEMP_DELAY=0.000000
_KV=35
_MA=40
_RANGE_WL=1.788970
_3DPLANE=0
_2THETACPS
   0.0000    2348.5
   5.0000    2399.0
  10.0000    2504.5
  15.0000    2674.0
  20.0000    2759.0
  25.0000    2974.5
  30.0000    3010.0
  35.0000    3279.5
  40.0000    3352.0
  45.0000    3303.0
  50.0000    3422.0
  55.0000    3297.5
  60.0000    3176.0
  65.0000    3175.5
  70.0000    3150.5
  75.0000    2985.5
  80.0000    3012.5
  85.0000    2924.5
  90.0000    3014.5
  95.0000    3054.0
 100.0000    3039.0
 105.0000    3063.0
 110.0000    3023.0
 115.0000    2946.0
 120.0000    2916.0
 125.0000    2850.5
 130.0000    2789.0
 135.0000    2631.5
 140.0000    2490.5
 145.0000    2389.5
 150.0000    2270.5
 155.0000    2121.5
 160.0000    2041.0
 165.0000    2035.5
 170.0000    2031.5
 175.0000    1982.0
 180.0000    1998.5
 185.0000    2117.0
 190.0000    2123.5
 195.0000    2249.0
 200.0000    2327.5
 205.0000    2473.5
 210.0000    2763.5
 215.0000    2835.5
 220.0000    3104.0
 225.0000    3215.5
 230.0000    3303.5
 235.0000    3234.0
 240.0000    3138.5
 245.0000    3118.0
 250.0000    3004.0
 255.0000    2946.0
 260.0000    2987.0
 265.0000    2959.0
 270.0000    3011.0
 275.0000    3006.5
 280.0000    3110.5
 285.0000    3195.5
 290.0000    3185.0
 295.0000    3088.0
 300.0000    3196.0
 305.0000    3108.0
 310.0000    2992.0
 315.0000    2923.0
 320.0000    2778.5
 325.0000    2675.5
 330.0000    2515.0
 335.0000    2415.0
 340.0000    2340.0
 345.0000    2278.0
 350.0000    2277.0
 355.0000    2280.5
; (Data for Range number 11)
_DRIVE='PHI'
_STEPTIME=2.000000
_STEPSIZE=5.000000
_STEPMODE='C'
_START=0.000000
_THETA=29.850000
_2THETA=59.700001
_KHI=50.000000
_PHI=0.000000
_X=0.000000
_Y=0.000000
_Z=0.000000
_DIVERGENCE=3.000000
_ANTISCATTER=3.000000
_DETECTOR=1
; S.C.
_HV=687.000000
_GAIN=80.000000
_LLD=0.690000
_ULD=1.866000
_DETECTORSLIT='unkn'
_AUX1=0.000000
_AUX2=0.000000
_AUX3=0.000000
_TIMESTARTED=2064.000000
_TEMP_RATE=0.000000
_TEMP_DELAY=0.000000
_KV=35
_MA=40
_RANGE_WL=1.788970
_3DPLANE=0
_2THETACPS
   0.0000    2152.5
   5.0000    2168.0
  10.0000    2294.5
  15.0000    2441.0
  20.0000    2575.5
  25.0000    2711.0
  30.0000    2907.5
  35.0000    3047.5
  40.0000    3145.5
  45.0000    3162.0
  50.0000    3284.5
  55.0000    3319.5
  60.0000    3199.0
  65.0000    3115.0
  70.0000    3107.0
  75.0000    3024.5
  80.0000    3020.5
  85.0000    2931.5
  90.0000    3021.0
  95.0000    2995.0
 100.0000    2990.5
 105.0000    2915.0
 110.0000    2912.5
 115.0000    2861.0
 120.0000    2840.0
 125.0000    2688.5
 130.0000    2608.0
 135.0000    2476.0
 140.0000    2311.0
 145.0000    2164.0
 150.0000    2032.0
 155.0000    1991.5
 160.0000    1921.0
 165.0000    1888.0
 170.0000    1843.5
 175.0000    1875.0
 180.0000    1895.5
 185.0000    2005.0
 190.0000    2021.5
 195.0000    2096.0
 200.0000    2226.0
 205.0000    2335.0
 210.0000    2539.5
 215.0000    2786.5
 220.0000    2925.0
 225.0000    3133.5
 230.0000    3176.0
 235.0000    3290.5
 240.0000    3045.0
 245.0000    2978.5
 250.0000    2966.0
 255.0000    2876.0
 260.0000    2834.5
 265.0000    2872.0
 270.0000    2971.0
 275.0000    2927.0
 280.0000    2907.5
 285.0000    2959.0
 290.0000    2955.0
 295.0000    3016.5
 300.0000    2972.5
 305.0000    2818.5
 310.0000    2766.0
 315.0000    2610.0
 320.0000    2457.0
 325.0000    2293.5
 330.0000    2218.0
 335.0000    2167.5
 340.0000    2097.5
 345.0000    2044.5
 350.0000    2128.5
 355.0000    2099.0
; (Data for Range number 12)
_DRIVE='PHI'
_STEPTIME=2.000000
_STEPSIZE=5.000000
_STEPMODE='C'
_START=0.000000
_THETA=29.850000
_2THETA=59.700001
_KHI=55.000000
_PHI=0.000000
_X=0.000000
_Y=0.000000
_Z=0.000000
_DIVERGENCE=3.000000
_ANTISCATTER=3.000000
_DETECTOR=1
; S.C.
_HV=687.000000
_GAIN=80.000000
_LLD=0.690000
_ULD=1.866000
_DETECTORSLIT='unkn'
_AUX1=0.000000
_AUX2=0.000000
_AUX3=0.000000
_TIMESTARTED=2269.000000
_TEMP_RATE=0.000000
_TEMP_DELAY=0.000000
_KV=35
_MA=40
_RANGE_WL=1.788970
_3DPLANE=0
_2THETACPS
   0.0000    1998.5
   5.0000    2107.0
  10.0000    2165.0
  15.0000    2249.5
  20.0000    2397.0
  25.0000    2510.0
  30.0000    2827.5
  35.0000    2897.0
  40.0000    3052.5
  45.0000    3173.0
  50.0000    3127.5
  55.0000    3152.5
  60.0000    3059.0
  65.0000    2988.0
  70.0000    2926.5
  75.0000    2876.5
  80.0000    2831.5
  85.0000    2872.0
  90.0000    2891.5
  95.0000    2795.0
 100.0000    2801.0
 105.0000    2769.5
 110.0000    2722.0
 115.0000    2595.0
 120.0000    2611.5
 125.0000    2502.5
 130.0000    2362.5
 135.0000    2206.0
 140.0000    2088.0
 145.0000    2048.5
 150.0000    1923.0
 155.0000    1832.0
 160.0000    1830.0
 165.0000    1798.0
 170.0000    1706.5
 175.0000    1762.0
 180.0000    1824.5
 185.0000    1903.5
 190.0000    1937.0
 195.0000    1966.0
 200.0000    2125.5
 205.0000    2265.0
 210.0000    2421.0
 215.0000    2574.0
 220.0000    2785.0
 225.0000    2974.5
 230.0000    3061.5
 235.0000    3074.0
 240.0000    2953.5
 245.0000    2925.5
 250.0000    2825.5
 255.0000    2770.5
 260.0000    2751.5
 265.0000    2794.5
 270.0000    2767.0
 275.0000    2775.0
 280.0000    2723.5
 285.0000    2803.5
 290.0000    2759.0
 295.0000    2661.5
 300.0000    2650.5
 305.0000    2549.5
 310.0000    2439.5
 315.0000    2305.0
 320.0000    2188.5
 325.0000    2027.5
 330.0000    1958.0
 335.0000    1843.5
 340.0000    1890.5
 345.0000    1879.0
 350.0000    1918.0
 355.0000    1895.5
; (Data for Range number 13)
_DRIVE='PHI'
_STEPTIME=2.000000
_STEPSIZE=5.000000
_STEPMODE='C'
_START=0.000000
_THETA=29.850000
_2THETA=59.700001
_KHI=60.000000
_PHI=0.000000
_X=0.000000
_Y=0.000000
_Z=0.000000
_DIVERGENCE=3.000000
_ANTISCATTER=3.000000
_DETECTOR=1
; S.C.
_HV=687.000000
_GAIN=80.000000
_LLD=0.690000
_ULD=1.866000
_DETECTORSLIT='unkn'
_AUX1=0.000000
_AUX2=0.000000
_AUX3=0.000000
_TIMESTARTED=2474.000000
_TEMP_RATE=0.000000
_TEMP_DELAY=0.000000
_KV=35
_MA=40
_RANGE_WL=1.788970
_3DPLANE=0
_2THETACPS
   0.0000    1768.0
   5.0000    1814.5
  10.0000    1930.5
  15.0000    2066.0
  20.0000    2195.5
  25.0000    2405.0
  30.0000    2621.5
  35.0000    2770.5
  40.0000    2869.0
  45.0000    2901.0
  50.0000    2976.0
  55.0000    2968.5
  60.0000    2924.0
  65.0000    2802.0
  70.0000    2803.0
  75.0000    2733.0
  80.0000    2751.5
  85.0000    2773.0
  90.0000    2666.5
  95.0000    2648.0
 100.0000    2566.0
 105.0000    2505.0
 110.0000    2429.5
 115.0000    2377.0
 120.0000    2332.0
 125.0000    2254.5
 130.0000    2163.5
 135.0000    2066.0
 140.0000    1946.0
 145.0000    1879.0
 150.0000    1736.5
 155.0000    1694.0
 160.0000    1632.0
 165.0000    1594.5
 170.0000    1660.5
 175.0000    1651.0
 180.0000    1718.0
 185.0000    1717.0
 190.0000    1789.5
 195.0000    1889.5
 200.0000    2008.5
 205.0000    2180.0
 210.0000    2268.5
 215.0000    2435.0
 220.0000    2613.5
 225.0000    2765.0
 230.0000    2916.5
 235.0000    2902.5
 240.0000    2801.5
 245.0000    2752.0
 250.0000    2679.5
 255.0000    2630.0
 260.0000    2658.5
 265.0000    2635.0
 270.0000    2576.5
 275.0000    2515.0
 280.0000    2540.0
 285.0000    2442.5
 290.0000    2434.5
 295.0000    2393.0
 300.0000    2315.5
 305.0000    2264.5
 310.0000    2103.0
 315.0000    2107.0
 320.0000    2019.5
 325.0000    1833.0
 330.0000    1720.0
 335.0000    1671.5
 340.0000    1674.0
 345.0000    1664.5
 350.0000    1671.0
 355.0000    1753.5
; (Data for Range number 14)
_DRIVE='PHI'
_STEPTIME=2.000000
_STEPSIZE=5.000000
_STEPMODE='C'
_START=0.000000
_THETA=29.850000
_2THETA=59.700001
_KHI=65.000000
_PHI=0.000000
_X=0.000000
_Y=0.000000
_Z=0.000000
_DIVERGENCE=3.000000
_ANTISCATTER=3.000000
_DETECTOR=1
; S.C.
_HV=687.000000
_GAIN=80.000000
_LLD=0.690000
_ULD=1.866000
_DETECTORSLIT='unkn'
_AUX1=0.000000
_AUX2=0.000000
_AUX3=0.000000
_TIMESTARTED=2678.000000
_TEMP_RATE=0.000000
_TEMP_DELAY=0.000000
_KV=35
_MA=40
_RANGE_WL=1.788970
_3DPLANE=0
_2THETACPS
   0.0000    1512.0
   5.0000    1630.5
  10.0000    1725.0
  15.0000    1886.0
  20.0000    1999.5
  25.0000    2176.5
  30.0000    2468.5
  35.0000    2590.5
  40.0000    2683.0
  45.0000    2747.0
  50.0000    2720.0
  55.0000    2687.0
  60.0000    2632.0
  65.0000    2659.5
  70.0000    2611.0
  75.0000    2566.5
  80.0000    2565.0
  85.0000    2520.0
  90.0000    2512.0
  95.0000    2413.0
 100.0000    2301.0
 105.0000    2167.0
 110.0000    2129.5
 115.0000    2066.0
 120.0000    1989.0
 125.0000    1981.0
 130.0000    1885.5
 135.0000    1751.5
 140.0000    1684.5
 145.0000    1594.5
 150.0000    1586.0
 155.0000    1449.0
 160.0000    1462.5
 165.0000    1445.5
 170.0000    1440.0
 175.0000    1458.0
 180.0000    1528.5
 185.0000    1527.5
 190.0000    1626.0
 195.0000    1763.0
 200.0000    1866.0
 205.0000    1983.0
 210.0000    2175.5
 215.0000    2330.5
 220.0000    2429.0
 225.0000    2583.5
 230.0000    2637.0
 235.0000    2637.5
 240.0000    2569.5
 245.0000    2572.5
 250.0000    2533.0
 255.0000    2451.0
 260.0000    2510.5
 265.0000    2433.0
 270.0000    2305.0
 275.0000    2263.5
 280.0000    2241.0
 285.0000    2140.0
 290.0000    2088.5
 295.0000    2046.0
 300.0000    1958.0
 305.0000    1928.5
 310.0000    1865.0
 315.0000    1798.5
 320.0000    1689.0
 325.0000    1661.5
 330.0000    1537.0
 335.0000    1468.5
 340.0000    1430.0
 345.0000    1406.0
 350.0000    1426.0
 355.0000    1490.0
; (Data for Range number 15)
_DRIVE='PHI'
_STEPTIME=2.000000
_STEPSIZE=5.000000
_STEPMODE='C'
_START=0.000000
_THETA=29.850000
_2THETA=59.700001
_KHI=70.000000
_PHI=0.000000
_X=0.000000
_Y=0.000000
_Z=0.000000
_DIVERGENCE=3.000000
_ANTISCATTER=3.000000
_DETECTOR=1
; S.C.
_HV=687.000000
_GAIN=80.000000
_LLD=0.690000
_ULD=1.866000
_DETECTORSLIT='unkn'
_AUX1=0.000000
_AUX2=0.000000
_AUX3=0.000000
_TIMESTARTED=2884.000000
_TEMP_RATE=0.000000
_TEMP_DELAY=0.000000
_KV=35
_MA=40
_RANGE_WL=1.788970
_3DPLANE=0
_2THETACPS
   0.0000    1271.5
   5.0000    1336.5
  10.0000    1422.0
  15.0000    1513.0
  20.0000    1675.5
  25.0000    1897.5
  30.0000    2118.5
  35.0000    2258.0
  40.0000    2412.5
  45.0000    2391.0
  50.0000    2286.0
  55.0000    2375.5
  60.0000    2251.0
  65.0000    2254.0
  70.0000    2267.0
  75.0000    2274.0
  80.0000    2276.5
  85.0000    2264.0
  90.0000    2266.5
  95.0000    2132.5
 100.0000    1995.0
 105.0000    1899.5
 110.0000    1771.0
 115.0000    1699.5
 120.0000    1716.0
 125.0000    1564.0
 130.0000    1628.0
 135.0000    1555.0
 140.0000    1478.0
 145.0000    1419.0
 150.0000    1367.5
 155.0000    1302.0
 160.0000    1202.5
 165.0000    1182.5
 170.0000    1240.0
 175.0000    1230.5
 180.0000    1252.5
 185.0000    1324.5
 190.0000    1388.0
 195.0000    1496.0
 200.0000    1654.5
 205.0000    1738.0
 210.0000    2012.0
 215.0000    2050.5
 220.0000    2190.5
 225.0000    2280.5
 230.0000    2297.5
 235.0000    2318.5
 240.0000    2272.0
 245.0000    2235.5
 250.0000    2249.0
 255.0000    2213.0
 260.0000    2296.0
 265.0000    2192.0
 270.0000    2030.0
 275.0000    1950.5
 280.0000    1842.5
 285.0000    1738.0
 290.0000    1694.0
 295.0000    1643.0
 300.0000    1613.0
 305.0000    1514.0
 310.0000    1469.5
 315.0000    1494.5
 320.0000    1463.5
 325.0000    1335.0
 330.0000    1363.0
 335.0000    1217.0
 340.0000    1218.5
 345.0000    1183.5
 350.0000    1227.0
 355.0000    1215.0
; (Data for Range number 16)
_DRIVE='PHI'
_STEPTIME=2.000000
_STEPSIZE=5.000000
_STEPMODE='C'
_START=0.000000
_THETA=29.850000
_2THETA=59.700001
_KHI=75.000000
_PHI=0.000000
_X=0.000000
_Y=0.000000
_Z=0.000000
_DIVERGENCE=3.000000
_ANTISCATTER=3.000000
_DETECTOR=1
; S.C.
_HV=687.000000
_GAIN=80.000000
_LLD=0.690000
_ULD=1.866000
_DETECTORSLIT='unkn'
_AUX1=0.000000
_AUX2=0.000000
_AUX3=0.000000
_TIMESTARTED=3089.000000
_TEMP_RATE=0.000000
_TEMP_DELAY=0.000000
_KV=35
_MA=40
_RANGE_WL=1.788970
_3DPLANE=0
_2THETACPS
   0.0000    966.00
   5.0000    1045.5
  10.0000    1103.5
  15.0000    1272.0
  20.0000    1390.5
  25.0000    1455.0
  30.0000    1724.5
  35.0000    1798.0
  40.0000    1845.5
  45.0000    1977.0
  50.0000    1844.0
  55.0000    1898.0
  60.0000    1860.0
  65.0000    1809.0
  70.0000    1778.0
  75.0000    1869.0
  80.0000    1882.5
  85.0000    1894.0
  90.0000    1846.0
  95.0000    1715.0
 100.0000    1634.0
 105.0000    1517.0
 110.0000    1410.5
 115.0000    1309.0
 120.0000    1294.5
 125.0000    1311.0
 130.0000    1258.0
 135.0000    1234.0
 140.0000    1192.0
 145.0000    1128.0
 150.0000    1130.5
 155.0000    1061.0
 160.0000    992.00
 165.0000    976.00
 170.0000    1006.0
 175.0000    987.50
 180.0000    1031.0
 185.0000    1083.0
 190.0000    1090.0
 195.0000    1187.5
 200.0000    1314.0
 205.0000    1474.0
 210.0000    1591.5
 215.0000    1748.5
 220.0000    1781.0
 225.0000    1818.5
 230.0000    1834.5
 235.0000    1773.0
 240.0000    1809.5
 245.0000    1783.5
 250.0000    1789.0
 255.0000    1921.5
 260.0000    1859.5
 265.0000    1786.5
 270.0000    1667.5
 275.0000    1494.0
 280.0000    1434.0
 285.0000    1301.0
 290.0000    1195.5
 295.0000    1215.0
 300.0000    1189.0
 305.0000    1221.0
 310.0000    1192.5
 315.0000    1198.0
 320.0000    1108.0
 325.0000    1040.5
 330.0000    980.00
 335.0000    956.00
 340.0000    948.50
 345.0000    932.50
 350.0000    987.50
 355.0000    957.00
; (Data for Range number 17)
_DRIVE='PHI'
_STEPTIME=2.000000
_STEPSIZE=5.000000
_STEPMODE='C'
_START=0.000000
_THETA=29.850000
_2THETA=59.700001
_KHI=80.000000
_PHI=0.000000
_X=0.000000
_Y=0.000000
_Z=0.000000
_DIVERGENCE=3.000000
_ANTISCATTER=3.000000
_DETECTOR=1
; S.C.
_HV=687.000000
_GAIN=80.000000
_LLD=0.690000
_ULD=1.866000
_DETECTORSLIT='unkn'
_AUX1=0.000000
_AUX2=0.000000
_AUX3=0.000000
_TIMESTARTED=3294.000000
_TEMP_RATE=0.000000
_TEMP_DELAY=0.000000
_KV=35
_MA=40
_RANGE_WL=1.788970
_3DPLANE=0
_2THETACPS
   0.0000    731.50
   5.0000    769.50
  10.0000    752.50
  15.0000    840.00
  20.0000    922.00
  25.0000    1070.5
  30.0000    1151.5
  35.0000    1254.5
  40.0000    1324.5
  45.0000    1333.5
  50.0000    1322.0
  55.0000    1351.5
  60.0000    1270.5
  65.0000    1342.0
  70.0000    1283.0
  75.0000    1225.0
  80.0000    1262.0
  85.0000    1324.5
  90.0000    1311.5
  95.0000    1209.5
 100.0000    1199.0
 105.0000    1042.0
 110.0000    1056.0
 115.0000    934.50
 120.0000    946.00
 125.0000    871.50
 130.0000    910.50
 135.0000    923.50
 140.0000    904.50
 145.0000    825.00
 150.0000    777.50
 155.0000    760.00
 160.0000    719.00
 165.0000    714.00
 170.0000    715.00
 175.0000    682.50
 180.0000    775.50
 185.0000    744.00
 190.0000    779.50
 195.0000    842.50
 200.0000    913.00
 205.0000    1030.0
 210.0000    1121.5
 215.0000    1150.5
 220.0000    1256.5
 225.0000    1309.0
 230.0000    1231.0
 235.0000    1209.0
 240.0000    1204.0
 245.0000    1186.5
 250.0000    1255.0
 255.0000    1265.0
 260.0000    1298.0
 265.0000    1230.5
 270.0000    1108.5
 275.0000    988.00
 280.0000    930.50
 285.0000    835.00
 290.0000    776.00
 295.0000    775.50
 300.0000    823.50
 305.0000    778.00
 310.0000    797.50
 315.0000    798.00
 320.0000    779.50
 325.0000    769.00
 330.0000    711.50
 335.0000    708.00
 340.0000    645.00
 345.0000    659.50
 350.0000    695.00
 355.0000    663.50
; (Data for Range number 18)
_DRIVE='PHI'
_STEPTIME=10.000000
_STEPSIZE=5.000000
_STEPMODE='S'
_START=0.000000
_THETA=28.000000
_2THETA=56.000000
_KHI=0.000000
_PHI=0.000000
_X=0.000000
_Y=0.000000
_Z=0.000000
_DIVERGENCE=3.000000
_ANTISCATTER=3.000000
_DETECTOR=1
; S.C.
_HV=687.000000
_GAIN=80.000000
_LLD=0.690000
_ULD=1.866000
_DETECTORSLIT='unkn'
_AUX1=0.000000
_AUX2=0.000000
_AUX3=0.000000
_TIMESTARTED=3496.000000
_TEMP_RATE=0.000000
_TEMP_DELAY=0.000000
_KV=35
_MA=40
_RANGE_WL=1.788970
_3DPLANE=0
_2THETACPS
   0.0000    2143.5
; (Data for Range number 19)
_DRIVE='PHI'
_STEPTIME=10.000000
_STEPSIZE=5.000000
_STEPMODE='S'
_START=0.000000
_THETA=28.000000
_2THETA=56.000000
_KHI=5.000000
_PHI=0.000000
_X=0.000000
_Y=0.000000
_Z=0.000000
_DIVERGENCE=3.000000
_ANTISCATTER=3.000000
_DETECTOR=1
; S.C.
_HV=687.000000
_GAIN=80.000000
_LLD=0.690000
_ULD=1.866000
_DETECTORSLIT='unkn'
_AUX1=0.000000
_AUX2=0.000000
_AUX3=0.000000
_TIMESTARTED=3511.000000
_TEMP_RATE=0.000000
_TEMP_DELAY=0.000000
_KV=35
_MA=40
_RANGE_WL=1.788970
_3DPLANE=0
_2THETACPS
   0.0000    2156.9
; (Data for Range number 20)
_DRIVE='PHI'
_STEPTIME=10.000000
_STEPSIZE=5.000000
_STEPMODE='S'
_START=0.000000
_THETA=28.000000
_2THETA=56.000000
_KHI=10.000000
_PHI=0.000000
_X=0.000000
_Y=0.000000
_Z=0.000000
_DIVERGENCE=3.000000
_ANTISCATTER=3.000000
_DETECTOR=1
; S.C.
_HV=687.000000
_GAIN=80.000000
_LLD=0.690000
_ULD=1.866000
_DETECTORSLIT='unkn'
_AUX1=0.000000
_AUX2=0.000000
_AUX3=0.000000
_TIMESTARTED=3526.000000
_TEMP_RATE=0.000000
_TEMP_DELAY=0.000000
_KV=35
_MA=40
_RANGE_WL=1.788970
_3DPLANE=0
_2THETACPS
   0.0000    2160.8
; (Data for Range number 21)
_DRIVE='PHI'
_STEPTIME=10.000000
_STEPSIZE=5.000000
_STEPMODE='S'
_START=0.000000
_THETA=28.000000
_2THETA=56.000000
_KHI=15.000000
_PHI=0.000000
_X=0.000000
_Y=0.000000
_Z=0.000000
_DIVERGENCE=3.000000
_ANTISCATTER=3.000000
_DETECTOR=1
; S.C.
_HV=687.000000
_GAIN=80.000000
_LLD=0.690000
_ULD=1.866000
_DETECTORSLIT='unkn'
_AUX1=0.000000
_AUX2=0.000000
_AUX3=0.000000
_TIMESTARTED=3541.000000
_TEMP_RATE=0.000000
_TEMP_DELAY=0.000000
_KV=35
_MA=40
_RANGE_WL=1.788970
_3DPLANE=0
_2THETACPS
   0.0000    2181.9
; (Data for Range number 22)
_DRIVE='PHI'
_STEPTIME=10.000000
_STEPSIZE=5.000000
_STEPMODE='S'
_START=0.000000
_THETA=28.000000
_2THETA=56.000000
_KHI=20.000000
_PHI=0.000000
_X=0.000000
_Y=0.000000
_Z=0.000000
_DIVERGENCE=3.000000
_ANTISCATTER=3.000000
_DETECTOR=1
; S.C.
_HV=687.000000
_GAIN=80.000000
_LLD=0.690000
_ULD=1.866000
_DETECTORSLIT='unkn'
_AUX1=0.000000
_AUX2=0.000000
_AUX3=0.000000
_TIMESTARTED=3556.000000
_TEMP_RATE=0.000000
_TEMP_DELAY=0.000000
_KV=35
_MA=40
_RANGE_WL=1.788970
_3DPLANE=0
_2THETACPS
   0.0000    2174.7
; (Data for Range number 23)
_DRIVE='PHI'
_STEPTIME=10.000000
_STEPSIZE=5.000000
_STEPMODE='S'
_START=0.000000
_THETA=28.000000
_2THETA=56.000000
_KHI=25.000000
_PHI=0.000000
_X=0.000000
_Y=0.000000
_Z=0.000000
_DIVERGENCE=3.000000
_ANTISCATTER=3.000000
_DETECTOR=1
; S.C.
_HV=687.000000
_GAIN=80.000000
_LLD=0.690000
_ULD=1.866000
_DETECTORSLIT='unkn'
_AUX1=0.000000
_AUX2=0.000000
_AUX3=0.000000
_TIMESTARTED=3571.000000
_TEMP_RATE=0.000000
_TEMP_DELAY=0.000000
_KV=35
_MA=40
_RANGE_WL=1.788970
_3DPLANE=0
_2THETACPS
   0.0000    2256.3
; (Data for Range number 24)
_DRIVE='PHI'
_STEPTIME=10.000000
_STEPSIZE=5.000000
_STEPMODE='S'
_START=0.000000
_THETA=28.000000
_2THETA=56.000000
_KHI=30.000000
_PHI=0.000000
_X=0.000000
_Y=0.000000
_Z=0.000000
_DIVERGENCE=3.000000
_ANTISCATTER=3.000000
_DETECTOR=1
; S.C.
_HV=687.000000
_GAIN=80.000000
_LLD=0.690000
_ULD=1.866000
_DETECTORSLIT='unkn'
_AUX1=0.000000
_AUX2=0.000000
_AUX3=0.000000
_TIMESTARTED=3586.000000
_TEMP_RATE=0.000000
_TEMP_DELAY=0.000000
_KV=35
_MA=40
_RANGE_WL=1.788970
_3DPLANE=0
_2THETACPS
   0.0000    2216.0
; (Data for Range number 25)
_DRIVE='PHI'
_STEPTIME=10.000000
_STEPSIZE=5.000000
_STEPMODE='S'
_START=0.000000
_THETA=28.000000
_2THETA=56.000000
_KHI=35.000000
_PHI=0.000000
_X=0.000000
_Y=0.000000
_Z=0.000000
_DIVERGENCE=3.000000
_ANTISCATTER=3.000000
_DETECTOR=1
; S.C.
_HV=687.000000
_GAIN=80.000000
_LLD=0.690000
_ULD=1.866000
_DETECTORSLIT='unkn'
_AUX1=0.000000
_AUX2=0.000000
_AUX3=0.000000
_TIMESTARTED=3601.000000
_TEMP_RATE=0.000000
_TEMP_DELAY=0.000000
_KV=35
_MA=40
_RANGE_WL=1.788970
_3DPLANE=0
_2THETACPS
   0.0000    2167.5
; (Data for Range number 26)
_DRIVE='PHI'
_STEPTIME=10.000000
_STEPSIZE=5.000000
_STEPMODE='S'
_START=0.000000
_THETA=28.000000
_2THETA=56.000000
_KHI=40.000000
_PHI=0.000000
_X=0.000000
_Y=0.000000
_Z=0.000000
_DIVERGENCE=3.000000
_ANTISCATTER=3.000000
_DETECTOR=1
; S.C.
_HV=687.000000
_GAIN=80.000000
_LLD=0.690000
_ULD=1.866000
_DETECTORSLIT='unkn'
_AUX1=0.000000
_AUX2=0.000000
_AUX3=0.000000
_TIMESTARTED=3616.000000
_TEMP_RATE=0.000000
_TEMP_DELAY=0.000000
_KV=35
_MA=40
_RANGE_WL=1.788970
_3DPLANE=0
_2THETACPS
   0.0000    2045.0
; (Data for Range number 27)
_DRIVE='PHI'
_STEPTIME=10.000000
_STEPSIZE=5.000000
_STEPMODE='S'
_START=0.000000
_THETA=28.000000
_2THETA=56.000000
_KHI=45.000000
_PHI=0.000000
_X=0.000000
_Y=0.000000
_Z=0.000000
_DIVERGENCE=3.000000
_ANTISCATTER=3.000000
_DETECTOR=1
; S.C.
_HV=687.000000
_GAIN=80.000000
_LLD=0.690000
_ULD=1.866000
_DETECTORSLIT='unkn'
_AUX1=0.000000
_AUX2=0.000000
_AUX3=0.000000
_TIMESTARTED=3631.000000
_TEMP_RATE=0.000000
_TEMP_DELAY=0.000000
_KV=35
_MA=40
_RANGE_WL=1.788970
_3DPLANE=0
_2THETACPS
   0.0000    1917.4
; (Data for Range number 28)
_DRIVE='PHI'
_STEPTIME=10.000000
_STEPSIZE=5.000000
_STEPMODE='S'
_START=0.000000
_THETA=28.000000
_2THETA=56.000000
_KHI=50.000000
_PHI=0.000000
_X=0.000000
_Y=0.000000
_Z=0.000000
_DIVERGENCE=3.000000
_ANTISCATTER=3.000000
_DETECTOR=1
; S.C.
_HV=687.000000
_GAIN=80.000000
_LLD=0.690000
_ULD=1.866000
_DETECTORSLIT='unkn'
_AUX1=0.000000
_AUX2=0.000000
_AUX3=0.000000
_TIMESTARTED=3646.000000
_TEMP_RATE=0.000000
_TEMP_DELAY=0.000000
_KV=35
_MA=40
_RANGE_WL=1.788970
_3DPLANE=0
_2THETACPS
   0.0000    1796.2
; (Data for Range number 29)
_DRIVE='PHI'
_STEPTIME=10.000000
_STEPSIZE=5.000000
_STEPMODE='S'
_START=0.000000
_THETA=28.000000
_2THETA=56.000000
_KHI=55.000000
_PHI=0.000000
_X=0.000000
_Y=0.000000
_Z=0.000000
_DIVERGENCE=3.000000
_ANTISCATTER=3.000000
_DETECTOR=1
; S.C.
[...]
_TIMESTARTED=22945.000000
_TEMP_RATE=0.000000
_TEMP_DELAY=0.000000
_KV=35
_MA=40
_RANGE_WL=1.788970
_3DPLANE=0
_2THETACPS
   0.0000    2401.5
   5.0000    2652.5
  10.0000    2772.5
  15.0000    2665.0
  20.0000    2644.0
  25.0000    2646.0
  30.0000    2617.5
  35.0000    2527.5
  40.0000    2546.0
  45.0000    2481.0
  50.0000    2518.0
  55.0000    2614.0
  60.0000    2548.5
  65.0000    2390.5
  70.0000    2197.0
  75.0000    2048.5
  80.0000    1938.0
  85.0000    1827.5
  90.0000    1846.5
  95.0000    1769.0
 100.0000    1695.0
 105.0000    1680.0
 110.0000    1640.0
 115.0000    1580.0
 120.0000    1583.5
 125.0000    1614.0
 130.0000    1638.5
 135.0000    1735.5
 140.0000    1680.5
 145.0000    1678.0
 150.0000    1618.0
 155.0000    1590.0
 160.0000    1702.0
 165.0000    1687.5
 170.0000    1915.0
 175.0000    2108.5
 180.0000    2257.0
 185.0000    2355.0
 190.0000    2488.0
 195.0000    2550.5
 200.0000    2611.0
 205.0000    2695.5
 210.0000    2591.0
 215.0000    2604.0
 220.0000    2568.0
 225.0000    2666.5
 230.0000    2691.0
 235.0000    2492.0
 240.0000    2455.0
 245.0000    2142.5
 250.0000    1964.5
 255.0000    1873.5
 260.0000    1731.0
 265.0000    1670.0
 270.0000    1701.0
 275.0000    1615.5
 280.0000    1594.5
 285.0000    1602.0
 290.0000    1522.0
 295.0000    1478.0
 300.0000    1543.0
 305.0000    1491.0
 310.0000    1481.5
 315.0000    1562.5
 320.0000    1545.0
 325.0000    1579.5
 330.0000    1526.0
 335.0000    1597.5
 340.0000    1669.5
 345.0000    1752.0
 350.0000    1966.0
 355.0000    2243.5
; (Data for Range number 239)
_DRIVE='PHI'
_STEPTIME=10.000000
_STEPSIZE=5.000000
_STEPMODE='S'
_START=0.000000
_THETA=59.000000
_2THETA=118.000000
_KHI=0.000000
_PHI=0.000000
_X=0.000000
_Y=0.000000
_Z=0.000000
_DIVERGENCE=3.000000
_ANTISCATTER=3.000000
_DETECTOR=1
; S.C.
_HV=687.000000
_GAIN=80.000000
_LLD=0.690000
_ULD=1.866000
_DETECTORSLIT='unkn'
_AUX1=0.000000
_AUX2=0.000000
_AUX3=0.000000
_TIMESTARTED=23147.000000
_TEMP_RATE=0.000000
_TEMP_DELAY=0.000000
_KV=35
_MA=40
_RANGE_WL=1.788970
_3DPLANE=0
_2THETACPS
   0.0000    2250.9
; (Data for Range number 240)
_DRIVE='PHI'
_STEPTIME=10.000000
_STEPSIZE=5.000000
_STEPMODE='S'
_START=0.000000
_THETA=59.000000
_2THETA=118.000000
_KHI=5.000000
_PHI=0.000000
_X=0.000000
_Y=0.000000
_Z=0.000000
_DIVERGENCE=3.000000
_ANTISCATTER=3.000000
_DETECTOR=1
; S.C.
_HV=687.000000
_GAIN=80.000000
_LLD=0.690000
_ULD=1.866000
_DETECTORSLIT='unkn'
_AUX1=0.000000
_AUX2=0.000000
_AUX3=0.000000
_TIMESTARTED=23162.000000
_TEMP_RATE=0.000000
_TEMP_DELAY=0.000000
_KV=35
_MA=40
_RANGE_WL=1.788970
_3DPLANE=0
_2THETACPS
   0.0000    2228.7
; (Data for Range number 241)
_DRIVE='PHI'
_STEPTIME=10.000000
_STEPSIZE=5.000000
_STEPMODE='S'
_START=0.000000
_THETA=59.000000
_2THETA=118.000000
_KHI=10.000000
_PHI=0.000000
_X=0.000000
_Y=0.000000
_Z=0.000000
_DIVERGENCE=3.000000
_ANTISCATTER=3.000000
_DETECTOR=1
; S.C.
_HV=687.000000
_GAIN=80.000000
_LLD=0.690000
_ULD=1.866000
_DETECTORSLIT='unkn'
_AUX1=0.000000
_AUX2=0.000000
_AUX3=0.000000
_TIMESTARTED=23177.000000
_TEMP_RATE=0.000000
_TEMP_DELAY=0.000000
_KV=35
_MA=40
_RANGE_WL=1.788970
_3DPLANE=0
_2THETACPS
   0.0000    2256.8
; (Data for Range number 242)
_DRIVE='PHI'
_STEPTIME=10.000000
_STEPSIZE=5.000000
_STEPMODE='S'
_START=0.000000
_THETA=59.000000
_2THETA=118.000000
_KHI=15.000000
_PHI=0.000000
_X=0.000000
_Y=0.000000
_Z=0.000000
_DIVERGENCE=3.000000
_ANTISCATTER=3.000000
_DETECTOR=1
; S.C.
_HV=687.000000
_GAIN=80.000000
_LLD=0.690000
_ULD=1.866000
_DETECTORSLIT='unkn'
_AUX1=0.000000
_AUX2=0.000000
_AUX3=0.000000
_TIMESTARTED=23192.000000
_TEMP_RATE=0.000000
_TEMP_DELAY=0.000000
_KV=35
_MA=40
_RANGE_WL=1.788970
_3DPLANE=0
_2THETACPS
   0.0000    2252.6
; (Data for Range number 243)
_DRIVE='PHI'
_STEPTIME=10.000000
_STEPSIZE=5.000000
_STEPMODE='S'
_START=0.000000
_THETA=59.000000
_2THETA=118.000000
_KHI=20.000000
_PHI=0.000000
_X=0.000000
_Y=0.000000
_Z=0.000000
_DIVERGENCE=3.000000
_ANTISCATTER=3.000000
_DETECTOR=1
; S.C.
_HV=687.000000
_GAIN=80.000000
_LLD=0.690000
_ULD=1.866000
_DETECTORSLIT='unkn'
_AUX1=0.000000
_AUX2=0.000000
_AUX3=0.000000
_TIMESTARTED=23207.000000
_TEMP_RATE=0.000000
_TEMP_DELAY=0.000000
_KV=35
_MA=40
_RANGE_WL=1.788970
_3DPLANE=0
_2THETACPS
   0.0000    2277.3
; (Data for Range number 244)
_DRIVE='PHI'
_STEPTIME=10.000000
_STEPSIZE=5.000000
_STEPMODE='S'
_START=0.000000
_THETA=59.000000
_2THETA=118.000000
_KHI=25.000000
_PHI=0.000000
_X=0.000000
_Y=0.000000
_Z=0.000000
_DIVERGENCE=3.000000
_ANTISCATTER=3.000000
_DETECTOR=1
; S.C.
_HV=687.000000
_GAIN=80.000000
_LLD=0.690000
_ULD=1.866000
_DETECTORSLIT='unkn'
_AUX1=0.000000
_AUX2=0.000000
_AUX3=0.000000
_TIMESTARTED=23222.000000
_TEMP_RATE=0.000000
_TEMP_DELAY=0.000000
_KV=35
_MA=40
_RANGE_WL=1.788970
_3DPLANE=0
_2THETACPS
   0.0000    2305.1
; (Data for Range number 245)
_DRIVE='PHI'
_STEPTIME=10.000000
_STEPSIZE=5.000000
_STEPMODE='S'
_START=0.000000
_THETA=59.000000
_2THETA=118.000000
_KHI=30.000000
_PHI=0.000000
_X=0.000000
_Y=0.000000
_Z=0.000000
_DIVERGENCE=3.000000
_ANTISCATTER=3.000000
_DETECTOR=1
; S.C.
_HV=687.000000
_GAIN=80.000000
_LLD=0.690000
_ULD=1.866000
_DETECTORSLIT='unkn'
_AUX1=0.000000
_AUX2=0.000000
_AUX3=0.000000
_TIMESTARTED=23237.000000
_TEMP_RATE=0.000000
_TEMP_DELAY=0.000000
_KV=35
_MA=40
_RANGE_WL=1.788970
_3DPLANE=0
_2THETACPS
   0.0000    2293.5
; (Data for Range number 246)
_DRIVE='PHI'
_STEPTIME=10.000000
_STEPSIZE=5.000000
_STEPMODE='S'
_START=0.000000
_THETA=59.000000
_2THETA=118.000000
_KHI=35.000000
_PHI=0.000000
_X=0.000000
_Y=0.000000
_Z=0.000000
_DIVERGENCE=3.000000
_ANTISCATTER=3.000000
_DETECTOR=1
; S.C.
_HV=687.000000
_GAIN=80.000000
_LLD=0.690000
_ULD=1.866000
_DETECTORSLIT='unkn'
_AUX1=0.000000
_AUX2=0.000000
_AUX3=0.000000
_TIMESTARTED=23252.000000
_TEMP_RATE=0.000000
_TEMP_DELAY=0.000000
_KV=35
_MA=40
_RANGE_WL=1.788970
_3DPLANE=0
_2THETACPS
   0.0000    2293.3
; (Data for Range number 247)
_DRIVE='PHI'
_STEPTIME=10.000000
_STEPSIZE=5.000000
_STEPMODE='S'
_START=0.000000
_THETA=59.000000
_2THETA=118.000000
_KHI=40.000000
_PHI=0.000000
_X=0.000000
_Y=0.000000
_Z=0.000000
_DIVERGENCE=3.000000
_ANTISCATTER=3.000000
_DETECTOR=1
; S.C.
_HV=687.000000
_GAIN=80.000000
_LLD=0.690000
_ULD=1.866000
_DETECTORSLIT='unkn'
_AUX1=0.000000
_AUX2=0.000000
_AUX3=0.000000
_TIMESTARTED=23267.000000
_TEMP_RATE=0.000000
_TEMP_DELAY=0.000000
_KV=35
_MA=40
_RANGE_WL=1.788970
_3DPLANE=0
_2THETACPS
   0.0000    2285.6
; (Data for Range number 248)
_DRIVE='PHI'
_STEPTIME=10.000000
_STEPSIZE=5.000000
_STEPMODE='S'
_START=0.000000
_THETA=59.000000
_2THETA=118.000000
_KHI=45.000000
_PHI=0.000000
_X=0.000000
_Y=0.000000
_Z=0.000000
_DIVERGENCE=3.000000
_ANTISCATTER=3.000000
_DETECTOR=1
; S.C.
_HV=687.000000
_GAIN=80.000000
_LLD=0.690000
_ULD=1.866000
_DETECTORSLIT='unkn'
_AUX1=0.000000
_AUX2=0.000000
_AUX3=0.000000
_TIMESTARTED=23282.000000
_TEMP_RATE=0.000000
_TEMP_DELAY=0.000000
_KV=35
_MA=40
_RANGE_WL=1.788970
_3DPLANE=0
_2THETACPS
   0.0000    2271.2
; (Data for Range number 249)
_DRIVE='PHI'
_STEPTIME=10.000000
_STEPSIZE=5.000000
_STEPMODE='S'
_START=0.000000
_THETA=59.000000
_2THETA=118.000000
_KHI=50.000000
_PHI=0.000000
_X=0.000000
_Y=0.000000
_Z=0.000000
_DIVERGENCE=3.000000
_ANTISCATTER=3.000000
_DETECTOR=1
; S.C.
_HV=687.000000
_GAIN=80.000000
_LLD=0.690000
_ULD=1.866000
_DETECTORSLIT='unkn'
_AUX1=0.000000
_AUX2=0.000000
_AUX3=0.000000
_TIMESTARTED=23297.000000
_TEMP_RATE=0.000000
_TEMP_DELAY=0.000000
_KV=35
_MA=40
_RANGE_WL=1.788970
_3DPLANE=0
_2THETACPS
   0.0000    2234.9
; (Data for Range number 250)
_DRIVE='PHI'
_STEPTIME=10.000000
_STEPSIZE=5.000000
_STEPMODE='S'
_START=0.000000
_THETA=59.000000
_2THETA=118.000000
_KHI=55.000000
_PHI=0.000000
_X=0.000000
_Y=0.000000
_Z=0.000000
_DIVERGENCE=3.000000
_ANTISCATTER=3.000000
_DETECTOR=1
; S.C.
_HV=687.000000
_GAIN=80.000000
_LLD=0.690000
_ULD=1.866000
_DETECTORSLIT='unkn'
_AUX1=0.000000
_AUX2=0.000000
_AUX3=0.000000
_TIMESTARTED=23312.000000
_TEMP_RATE=0.000000
_TEMP_DELAY=0.000000
_KV=35
_MA=40
_RANGE_WL=1.788970
_3DPLANE=0
_2THETACPS
   0.0000    2224.5
; (Data for Range number 251)
_DRIVE='PHI'
_STEPTIME=10.000000
_STEPSIZE=5.000000
_STEPMODE='S'
_START=0.000000
_THETA=59.000000
_2THETA=118.000000
_KHI=60.000000
_PHI=0.000000
_X=0.000000
_Y=0.000000
_Z=0.000000
_DIVERGENCE=3.000000
_ANTISCATTER=3.000000
_DETECTOR=1
; S.C.
_HV=687.000000
_GAIN=80.000000
_LLD=0.690000
_ULD=1.866000
_DETECTORSLIT='unkn'
_AUX1=0.000000
_AUX2=0.000000
_AUX3=0.000000
_TIMESTARTED=23327.000000
_TEMP_RATE=0.000000
_TEMP_DELAY=0.000000
_KV=35
_MA=40
_RANGE_WL=1.788970
_3DPLANE=0
_2THETACPS
   0.0000    2258.3
; (Data for Range number 252)
_DRIVE='PHI'
_STEPTIME=10.000000
_STEPSIZE=5.000000
_STEPMODE='S'
_START=0.000000
_THETA=59.000000
_2THETA=118.000000
_KHI=65.000000
_PHI=0.000000
_X=0.000000
_Y=0.000000
_Z=0.000000
_DIVERGENCE=3.000000
_ANTISCATTER=3.000000
_DETECTOR=1
; S.C.
_HV=687.000000
_GAIN=80.000000
_LLD=0.690000
_ULD=1.866000
_DETECTORSLIT='unkn'
_AUX1=0.000000
_AUX2=0.000000
_AUX3=0.000000
_TIMESTARTED=23342.000000
_TEMP_RATE=0.000000
_TEMP_DELAY=0.000000
_KV=35
_MA=40
_RANGE_WL=1.788970
_3DPLANE=0
_2THETACPS
   0.0000    2257.6
; (Data for Range number 253)
_DRIVE='PHI'
_STEPTIME=10.000000
_STEPSIZE=5.000000
_STEPMODE='S'
_START=0.000000
_THETA=59.000000
_2THETA=118.000000
_KHI=70.000000
_PHI=0.000000
_X=0.000000
_Y=0.000000
_Z=0.000000
_DIVERGENCE=3.000000
_ANTISCATTER=3.000000
_DETECTOR=1
; S.C.
_HV=687.000000
_GAIN=80.000000
_LLD=0.690000
_ULD=1.866000
_DETECTORSLIT='unkn'
_AUX1=0.000000
_AUX2=0.000000
_AUX3=0.000000
_TIMESTARTED=23357.000000
_TEMP_RATE=0.000000
_TEMP_DELAY=0.000000
_KV=35
_MA=40
_RANGE_WL=1.788970
_3DPLANE=0
_2THETACPS
   0.0000    2182.6
; (Data for Range number 254)
_DRIVE='PHI'
_STEPTIME=10.000000
_STEPSIZE=5.000000
_STEPMODE='S'
_START=0.000000
_THETA=59.000000
_2THETA=118.000000
_KHI=75.000000
_PHI=0.000000
_X=0.000000
_Y=0.000000
_Z=0.000000
_DIVERGENCE=3.000000
_ANTISCATTER=3.000000
_DETECTOR=1
; S.C.
_HV=687.000000
_GAIN=80.000000
_LLD=0.690000
_ULD=1.866000
_DETECTORSLIT='unkn'
_AUX1=0.000000
_AUX2=0.000000
_AUX3=0.000000
_TIMESTARTED=23372.000000
_TEMP_RATE=0.000000
_TEMP_DELAY=0.000000
_KV=35
_MA=40
_RANGE_WL=1.788970
_3DPLANE=0
_2THETACPS
   0.0000    2037.2
; (Data for Range number 255)
_DRIVE='PHI'
_STEPTIME=10.000000
_STEPSIZE=5.000000
_STEPMODE='S'
_START=0.000000
_THETA=59.000000
_2THETA=118.000000
_KHI=80.000000
_PHI=0.000000
_X=0.000000
_Y=0.000000
_Z=0.000000
_DIVERGENCE=3.000000
_ANTISCATTER=3.000000
_DETECTOR=1
; S.C.
_HV=687.000000
_GAIN=80.000000
_LLD=0.690000
_ULD=1.866000
_DETECTORSLIT='unkn'
_AUX1=0.000000
_AUX2=0.000000
_AUX3=0.000000
_TIMESTARTED=23387.000000
_TEMP_RATE=0.000000
_TEMP_DELAY=0.000000
_KV=35
_MA=40
_RANGE_WL=1.788970
_3DPLANE=0
_2THETACPS
   0.0000    1680.2
; (Data for Range number 256)
_DRIVE='PHI'
_STEPTIME=10.000000
_STEPSIZE=5.000000
_STEPMODE='S'
_START=0.000000
_THETA=64.000000
_2THETA=128.000000
_KHI=0.000000
_PHI=0.000000
_X=0.000000
_Y=0.000000
_Z=0.000000
_DIVERGENCE=3.000000
_ANTISCATTER=3.000000
_DETECTOR=1
; S.C.
_HV=687.000000
_GAIN=80.000000
_LLD=0.690000
_ULD=1.866000
_DETECTORSLIT='unkn'
_AUX1=0.000000
_AUX2=0.000000
_AUX3=0.000000
_TIMESTARTED=23424.000000
_TEMP_RATE=0.000000
_TEMP_DELAY=0.000000
_KV=35
_MA=40
_RANGE_WL=1.788970
_3DPLANE=0
_2THETACPS
   0.0000    2237.4
; (Data for Range number 257)
_DRIVE='PHI'
_STEPTIME=10.000000
_STEPSIZE=5.000000
_STEPMODE='S'
_START=0.000000
_THETA=64.000000
_2THETA=128.000000
_KHI=5.000000
_PHI=0.000000
_X=0.000000
_Y=0.000000
_Z=0.000000
_DIVERGENCE=3.000000
_ANTISCATTER=3.000000
_DETECTOR=1
; S.C.
_HV=687.000000
_GAIN=80.000000
_LLD=0.690000
_ULD=1.866000
_DETECTORSLIT='unkn'
_AUX1=0.000000
_AUX2=0.000000
_AUX3=0.000000
_TIMESTARTED=23439.000000
_TEMP_RATE=0.000000
_TEMP_DELAY=0.000000
_KV=35
_MA=40
_RANGE_WL=1.788970
_3DPLANE=0
_2THETACPS
   0.0000    2231.7
; (Data for Range number 258)
_DRIVE='PHI'
_STEPTIME=10.000000
_STEPSIZE=5.000000
_STEPMODE='S'
_START=0.000000
_THETA=64.000000
_2THETA=128.000000
_KHI=10.000000
_PHI=0.000000
_X=0.000000
_Y=0.000000
_Z=0.000000
_DIVERGENCE=3.000000
_ANTISCATTER=3.000000
_DETECTOR=1
; S.C.
_HV=687.000000
_GAIN=80.000000
_LLD=0.690000
_ULD=1.866000
_DETECTORSLIT='unkn'
_AUX1=0.000000
_AUX2=0.000000
_AUX3=0.000000
_TIMESTARTED=23454.000000
_TEMP_RATE=0.000000
_TEMP_DELAY=0.000000
_KV=35
_MA=40
_RANGE_WL=1.788970
_3DPLANE=0
_2THETACPS
   0.0000    2243.6
; (Data for Range number 259)
_DRIVE='PHI'
_STEPTIME=10.000000
_STEPSIZE=5.000000
_STEPMODE='S'
_START=0.000000
_THETA=64.000000
_2THETA=128.000000
_KHI=15.000000
_PHI=0.000000
_X=0.000000
_Y=0.000000
_Z=0.000000
_DIVERGENCE=3.000000
_ANTISCATTER=3.000000
_DETECTOR=1
; S.C.
_HV=687.000000
_GAIN=80.000000
_LLD=0.690000
_ULD=1.866000
_DETECTORSLIT='unkn'
_AUX1=0.000000
_AUX2=0.000000
_AUX3=0.000000
_TIMESTARTED=23469.000000
_TEMP_RATE=0.000000
_TEMP_DELAY=0.000000
_KV=35
_MA=40
_RANGE_WL=1.788970
_3DPLANE=0
_2THETACPS
   0.0000    2216.7
; (Data for Range number 260)
_DRIVE='PHI'
_STEPTIME=10.000000
_STEPSIZE=5.000000
_STEPMODE='S'
_START=0.000000
_THETA=64.000000
_2THETA=128.000000
_KHI=20.000000
_PHI=0.000000
_X=0.000000
_Y=0.000000
_Z=0.000000
_DIVERGENCE=3.000000
_ANTISCATTER=3.000000
_DETECTOR=1
; S.C.
_HV=687.000000
_GAIN=80.000000
_LLD=0.690000
_ULD=1.866000
_DETECTORSLIT='unkn'
_AUX1=0.000000
_AUX2=0.000000
_AUX3=0.000000
_TIMESTARTED=23484.000000
_TEMP_RATE=0.000000
_TEMP_DELAY=0.000000
_KV=35
_MA=40
_RANGE_WL=1.788970
_3DPLANE=0
_2THETACPS
   0.0000    2229.2
; (Data for Range number 261)
_DRIVE='PHI'
_STEPTIME=10.000000
_STEPSIZE=5.000000
_STEPMODE='S'
_START=0.000000
_THETA=64.000000
_2THETA=128.000000
_KHI=25.000000
_PHI=0.000000
_X=0.000000
_Y=0.000000
_Z=0.000000
_DIVERGENCE=3.000000
_ANTISCATTER=3.000000
_DETECTOR=1
; S.C.
_HV=687.000000
_GAIN=80.000000
_LLD=0.690000
_ULD=1.866000
_DETECTORSLIT='unkn'
_AUX1=0.000000
_AUX2=0.000000
_AUX3=0.000000
_TIMESTARTED=23499.000000
_TEMP_RATE=0.000000
_TEMP_DELAY=0.000000
_KV=35
_MA=40
_RANGE_WL=1.788970
_3DPLANE=0
_2THETACPS
   0.0000    2263.1
; (Data for Range number 262)
_DRIVE='PHI'
_STEPTIME=10.000000
_STEPSIZE=5.000000
_STEPMODE='S'
_START=0.000000
_THETA=64.000000
_2THETA=128.000000
_KHI=30.000000
_PHI=0.000000
_X=0.000000
_Y=0.000000
_Z=0.000000
_DIVERGENCE=3.000000
_ANTISCATTER=3.000000
_DETECTOR=1
; S.C.
_HV=687.000000
_GAIN=80.000000
_LLD=0.690000
_ULD=1.866000
_DETECTORSLIT='unkn'
_AUX1=0.000000
_AUX2=0.000000
_AUX3=0.000000
_TIMESTARTED=23515.000000
_TEMP_RATE=0.000000
_TEMP_DELAY=0.000000
_KV=35
_MA=40
_RANGE_WL=1.788970
_3DPLANE=0
_2THETACPS
   0.0000    2249.8
; (Data for Range number 263)
_DRIVE='PHI'
_STEPTIME=10.000000
_STEPSIZE=5.000000
_STEPMODE='S'
_START=0.000000
_THETA=64.000000
_2THETA=128.000000
_KHI=35.000000
_PHI=0.000000
_X=0.000000
_Y=0.000000
_Z=0.000000
_DIVERGENCE=3.000000
_ANTISCATTER=3.000000
_DETECTOR=1
; S.C.
_HV=687.000000
_GAIN=80.000000
_LLD=0.690000
_ULD=1.866000
_DETECTORSLIT='unkn'
_AUX1=0.000000
_AUX2=0.000000
_AUX3=0.000000
_TIMESTARTED=23530.000000
_TEMP_RATE=0.000000
_TEMP_DELAY=0.000000
_KV=35
_MA=40
_RANGE_WL=1.788970
_3DPLANE=0
_2THETACPS
   0.0000    2265.8
; (Data for Range number 264)
_DRIVE='PHI'
_STEPTIME=10.000000
_STEPSIZE=5.000000
_STEPMODE='S'
_START=0.000000
_THETA=64.000000
_2THETA=128.000000
_KHI=40.000000
_PHI=0.000000
_X=0.000000
_Y=0.000000
_Z=0.000000
_DIVERGENCE=3.000000
_ANTISCATTER=3.000000
_DETECTOR=1
; S.C.
_HV=687.000000
_GAIN=80.000000
_LLD=0.690000
_ULD=1.866000
_DETECTORSLIT='unkn'
_AUX1=0.000000
_AUX2=0.000000
_AUX3=0.000000
_TIMESTARTED=23545.000000
_TEMP_RATE=0.000000
_TEMP_DELAY=0.000000
_KV=35
_MA=40
_RANGE_WL=1.788970
_3DPLANE=0
_2THETACPS
   0.0000    2208.1
; (Data for Range number 265)
_DRIVE='PHI'
_STEPTIME=10.000000
_STEPSIZE=5.000000
_STEPMODE='S'
_START=0.000000
_THETA=64.000000
_2THETA=128.000000
_KHI=45.000000
_PHI=0.000000
_X=0.000000
_Y=0.000000
_Z=0.000000
_DIVERGENCE=3.000000
_ANTISCATTER=3.000000
_DETECTOR=1
; S.C.
_HV=687.000000
_GAIN=80.000000
_LLD=0.690000
_ULD=1.866000
_DETECTORSLIT='unkn'
_AUX1=0.000000
_AUX2=0.000000
_AUX3=0.000000
_TIMESTARTED=23560.000000
_TEMP_RATE=0.000000
_TEMP_DELAY=0.000000
_KV=35
_MA=40
_RANGE_WL=1.788970
_3DPLANE=0
_2THETACPS
   0.0000    2225.0
; (Data for Range number 266)
_DRIVE='PHI'
_STEPTIME=10.000000
_STEPSIZE=5.000000
_STEPMODE='S'
_START=0.000000
_THETA=64.000000
_2THETA=128.000000
_KHI=50.000000
_PHI=0.000000
_X=0.000000
_Y=0.000000
_Z=0.000000
_DIVERGENCE=3.000000
_ANTISCATTER=3.000000
_DETECTOR=1
; S.C.
_HV=687.000000
_GAIN=80.000000
_LLD=0.690000
_ULD=1.866000
_DETECTORSLIT='unkn'
_AUX1=0.000000
_AUX2=0.000000
_AUX3=0.000000
_TIMESTARTED=23575.000000
_TEMP_RATE=0.000000
_TEMP_DELAY=0.000000
_KV=35
_MA=40
_RANGE_WL=1.788970
_3DPLANE=0
_2THETACPS
   0.0000    2236.8
; (Data for Range number 267)
_DRIVE='PHI'
_STEPTIME=10.000000
_STEPSIZE=5.000000
_STEPMODE='S'
_START=0.000000
_THETA=64.000000
_2THETA=128.000000
_KHI=55.000000
_PHI=0.000000
_X=0.000000
_Y=0.000000
_Z=0.000000
_DIVERGENCE=3.000000
_ANTISCATTER=3.000000
_DETECTOR=1
; S.C.
_HV=687.000000
_GAIN=80.000000
_LLD=0.690000
_ULD=1.866000
_DETECTORSLIT='unkn'
_AUX1=0.000000
_AUX2=0.000000
_AUX3=0.000000
_TIMESTARTED=23590.000000
_TEMP_RATE=0.000000
_TEMP_DELAY=0.000000
_KV=35
_MA=40
_RANGE_WL=1.788970
_3DPLANE=0
_2THETACPS
   0.0000    2227.2
; (Data for Range number 268)
_DRIVE='PHI'
_STEPTIME=10.000000
_STEPSIZE=5.000000
_STEPMODE='S'
_START=0.000000
_THETA=64.000000
_2THETA=128.000000
_KHI=60.000000
_PHI=0.000000
_X=0.000000
_Y=0.000000
_Z=0.000000
_DIVERGENCE=3.000000
_ANTISCATTER=3.000000
_DETECTOR=1
; S.C.
_HV=687.000000
_GAIN=80.000000
_LLD=0.690000
_ULD=1.866000
_DETECTORSLIT='unkn'
_AUX1=0.000000
_AUX2=0.000000
_AUX3=0.000000
_TIMESTARTED=23604.000000
_TEMP_RATE=0.000000
_TEMP_DELAY=0.000000
_KV=35
_MA=40
_RANGE_WL=1.788970
_3DPLANE=0
_2THETACPS
   0.0000    2258.7
; (Data for Range number 269)
_DRIVE='PHI'
_STEPTIME=10.000000
_STEPSIZE=5.000000
_STEPMODE='S'
_START=0.000000
_THETA=64.000000
_2THETA=128.000000
_KHI=65.000000
_PHI=0.000000
_X=0.000000
_Y=0.000000
_Z=0.000000
_DIVERGENCE=3.000000
_ANTISCATTER=3.000000
_DETECTOR=1
; S.C.
_HV=687.000000
_GAIN=80.000000
_LLD=0.690000
_ULD=1.866000
_DETECTORSLIT='unkn'
_AUX1=0.000000
_AUX2=0.000000
_AUX3=0.000000
_TIMESTARTED=23620.000000
_TEMP_RATE=0.000000
_TEMP_DELAY=0.000000
_KV=35
_MA=40
_RANGE_WL=1.788970
_3DPLANE=0
_2THETACPS
   0.0000    2245.5
; (Data for Range number 270)
_DRIVE='PHI'
_STEPTIME=10.000000
_STEPSIZE=5.000000
_STEPMODE='S'
_START=0.000000
_THETA=64.000000
_2THETA=128.000000
_KHI=70.000000
_PHI=0.000000
_X=0.000000
_Y=0.000000
_Z=0.000000
_DIVERGENCE=3.000000
_ANTISCATTER=3.000000
_DETECTOR=1
; S.C.
_HV=687.000000
_GAIN=80.000000
_LLD=0.690000
_ULD=1.866000
_DETECTORSLIT='unkn'
_AUX1=0.000000
_AUX2=0.000000
_AUX3=0.000000
_TIMESTARTED=23635.000000
_TEMP_RATE=0.000000
_TEMP_DELAY=0.000000
_KV=35
_MA=40
_RANGE_WL=1.788970
_3DPLANE=0
_2THETACPS
   0.0000    2206.2
; (Data for Range number 271)
_DRIVE='PHI'
_STEPTIME=10.000000
_STEPSIZE=5.000000
_STEPMODE='S'
_START=0.000000
_THETA=64.000000
_2THETA=128.000000
_KHI=75.000000
_PHI=0.000000
_X=0.000000
_Y=0.000000
_Z=0.000000
_DIVERGENCE=3.000000
_ANTISCATTER=3.000000
_DETECTOR=1
; S.C.
_HV=687.000000
_GAIN=80.000000
_LLD=0.690000
_ULD=1.866000
_DETECTORSLIT='unkn'
_AUX1=0.000000
_AUX2=0.000000
_AUX3=0.000000
_TIMESTARTED=23650.000000
_TEMP_RATE=0.000000
_TEMP_DELAY=0.000000
_KV=35
_MA=40
_RANGE_WL=1.788970
_3DPLANE=0
_2THETACPS
   0.0000    2168.0
; (Data for Range number 272)
_DRIVE='PHI'
_STEPTIME=10.000000
_STEPSIZE=5.000000
_STEPMODE='S'
_START=0.000000
_THETA=64.000000
_2THETA=128.000000
_KHI=80.000000
_PHI=0.000000
_X=0.000000
_Y=0.000000
_Z=0.000000
_DIVERGENCE=3.000000
_ANTISCATTER=3.000000
_DETECTOR=1
; S.C.
_HV=687.000000
_GAIN=80.000000
_LLD=0.690000
_ULD=1.866000
_DETECTORSLIT='unkn'
_AUX1=0.000000
_AUX2=0.000000
_AUX3=0.000000
_TIMESTARTED=23665.000000
_TEMP_RATE=0.000000
_TEMP_DELAY=0.000000
_KV=35
_MA=40
_RANGE_WL=1.788970
_3DPLANE=0
_2THETACPS
   0.0000    1934.6