File: exp_dat/old/6pfs_R.UXD
; C:\DIFFDAT1\GIFT\MML\youngung\14-02-06_TRIP_Seawoong\jobs\6pfs_R.raw(Diffrac Plus V1.01 file) converted by XCH V1.0
_FILEVERSION=2
_SITE='Korea'
_USER='Admin'
_SAMPLE_CHANGER_CODE=0
_ATTACHMENTS_CODE=0
_GONIOMETER_RADIUS=300.000000
_FIXED_DIVSLIT=1.000000
_FIXED_SAMPLESLIT=0.000000
_FIXED_DETSLIT=0.100000
_MONOCHROMATOR=0
; None
_THIN_FILM='N'
_BETA_FILTER='Y'
_FIXED_ANTISLIT=0.600000
_ANALYZER_CODE=0
; None
_DATEMEASURED='06-Feb-2014 18:48:59'
_WL_UNIT='A'
_WL1=1.788970
_WL2=1.792850
_WL3=1.620790
_WLRATIO=0.500000
_ANODE='Co'
; (Data for Range number 1)
_DRIVE='PHI'
_STEPTIME=2.000000
_STEPSIZE=5.000000
_STEPMODE='C'
_START=0.000000
_THETA=29.850000
_2THETA=59.700001
_KHI=0.000000
_PHI=0.000000
_X=0.000000
_Y=0.000000
_Z=0.000000
_DIVERGENCE=3.000000
_ANTISCATTER=3.000000
_DETECTOR=1
; S.C.
_HV=687.000000
_GAIN=80.000000
_LLD=0.690000
_ULD=1.866000
_DETECTORSLIT='unkn'
_AUX1=0.000000
_AUX2=0.000000
_AUX3=0.000000
_TIMESTARTED=15.000000
_TEMP_RATE=0.000000
_TEMP_DELAY=0.000000
_KV=35
_MA=40
_RANGE_WL=1.788970
_3DPLANE=0
_2THETACPS
   0.0000    2414.0
   5.0000    2384.5
  10.0000    2460.5
  15.0000    2354.0
  20.0000    2464.0
  25.0000    2418.5
  30.0000    2370.0
  35.0000    2454.0
  40.0000    2421.5
  45.0000    2394.0
  50.0000    2454.0
  55.0000    2448.0
  60.0000    2473.5
  65.0000    2327.0
  70.0000    2488.5
  75.0000    2433.5
  80.0000    2438.5
  85.0000    2461.5
  90.0000    2421.5
  95.0000    2423.5
 100.0000    2393.0
 105.0000    2436.5
 110.0000    2429.5
 115.0000    2388.5
 120.0000    2409.0
 125.0000    2394.5
 130.0000    2360.0
 135.0000    2371.5
 140.0000    2241.0
 145.0000    2219.5
 150.0000    2157.0
 155.0000    2146.0
 160.0000    2079.5
 165.0000    2016.0
 170.0000    2042.0
 175.0000    2002.5
 180.0000    2013.0
 185.0000    1969.5
 190.0000    1985.0
 195.0000    1959.5
 200.0000    1950.5
 205.0000    2071.5
 210.0000    2118.5
 215.0000    2113.5
 220.0000    2120.5
 225.0000    2183.0
 230.0000    2267.0
 235.0000    2421.0
 240.0000    2389.5
 245.0000    2504.5
 250.0000    2522.0
 255.0000    2526.5
 260.0000    2444.0
 265.0000    2549.0
 270.0000    2512.5
 275.0000    2553.5
 280.0000    2492.0
 285.0000    2578.5
 290.0000    2553.0
 295.0000    2537.0
 300.0000    2529.0
 305.0000    2551.5
 310.0000    2540.0
 315.0000    2509.0
 320.0000    2505.0
 325.0000    2497.0
 330.0000    2447.5
 335.0000    2446.0
 340.0000    2474.0
 345.0000    2463.0
 350.0000    2446.5
 355.0000    2401.5
; (Data for Range number 2)
_DRIVE='PHI'
_STEPTIME=2.000000
_STEPSIZE=5.000000
_STEPMODE='C'
_START=0.000000
_THETA=29.850000
_2THETA=59.700001
_KHI=5.000000
_PHI=0.000000
_X=0.000000
_Y=0.000000
_Z=0.000000
_DIVERGENCE=3.000000
_ANTISCATTER=3.000000
_DETECTOR=1
; S.C.
_HV=687.000000
_GAIN=80.000000
_LLD=0.690000
_ULD=1.866000
_DETECTORSLIT='unkn'
_AUX1=0.000000
_AUX2=0.000000
_AUX3=0.000000
_TIMESTARTED=220.000000
_TEMP_RATE=0.000000
_TEMP_DELAY=0.000000
_KV=35
_MA=40
_RANGE_WL=1.788970
_3DPLANE=0
_2THETACPS
   0.0000    2441.0
   5.0000    2481.0
  10.0000    2413.0
  15.0000    2401.0
  20.0000    2449.0
  25.0000    2451.5
  30.0000    2467.5
  35.0000    2437.0
  40.0000    2441.5
  45.0000    2426.5
  50.0000    2426.5
  55.0000    2484.0
  60.0000    2415.0
  65.0000    2363.5
  70.0000    2423.0
  75.0000    2478.5
  80.0000    2419.0
  85.0000    2455.5
  90.0000    2429.5
  95.0000    2429.5
 100.0000    2452.0
 105.0000    2453.5
 110.0000    2458.0
 115.0000    2430.0
 120.0000    2432.0
 125.0000    2402.0
 130.0000    2406.0
 135.0000    2288.0
 140.0000    2323.0
 145.0000    2111.5
 150.0000    2141.0
 155.0000    2175.5
 160.0000    2096.5
 165.0000    2036.0
 170.0000    2057.0
 175.0000    2086.0
 180.0000    2029.5
 185.0000    2043.0
 190.0000    2018.5
 195.0000    1976.5
 200.0000    2089.0
 205.0000    2068.5
 210.0000    2138.0
 215.0000    2180.5
 220.0000    2202.0
 225.0000    2265.5
 230.0000    2270.5
 235.0000    2396.5
 240.0000    2395.0
 245.0000    2543.0
 250.0000    2534.5
 255.0000    2500.5
 260.0000    2513.5
 265.0000    2479.0
 270.0000    2538.5
 275.0000    2490.5
 280.0000    2510.5
 285.0000    2573.0
 290.0000    2528.5
 295.0000    2469.5
 300.0000    2557.5
 305.0000    2497.5
 310.0000    2487.0
 315.0000    2558.0
 320.0000    2547.5
 325.0000    2444.0
 330.0000    2499.0
 335.0000    2437.5
 340.0000    2470.0
 345.0000    2400.5
 350.0000    2441.5
 355.0000    2415.0
; (Data for Range number 3)
_DRIVE='PHI'
_STEPTIME=2.000000
_STEPSIZE=5.000000
_STEPMODE='C'
_START=0.000000
_THETA=29.850000
_2THETA=59.700001
_KHI=10.000000
_PHI=0.000000
_X=0.000000
_Y=0.000000
_Z=0.000000
_DIVERGENCE=3.000000
_ANTISCATTER=3.000000
_DETECTOR=1
; S.C.
_HV=687.000000
_GAIN=80.000000
_LLD=0.690000
_ULD=1.866000
_DETECTORSLIT='unkn'
_AUX1=0.000000
_AUX2=0.000000
_AUX3=0.000000
_TIMESTARTED=425.000000
_TEMP_RATE=0.000000
_TEMP_DELAY=0.000000
_KV=35
_MA=40
_RANGE_WL=1.788970
_3DPLANE=0
_2THETACPS
   0.0000    2512.0
   5.0000    2474.0
  10.0000    2427.0
  15.0000    2476.5
  20.0000    2461.0
  25.0000    2440.5
  30.0000    2435.0
  35.0000    2488.5
  40.0000    2491.0
  45.0000    2459.0
  50.0000    2453.0
  55.0000    2383.5
  60.0000    2450.5
  65.0000    2495.5
  70.0000    2517.5
  75.0000    2420.5
  80.0000    2473.0
  85.0000    2438.5
  90.0000    2456.5
  95.0000    2401.0
 100.0000    2407.0
 105.0000    2457.5
 110.0000    2405.5
 115.0000    2450.5
 120.0000    2466.5
 125.0000    2361.0
 130.0000    2351.5
 135.0000    2280.0
 140.0000    2203.5
 145.0000    2284.0
 150.0000    2198.5
 155.0000    2145.5
 160.0000    2157.0
 165.0000    2145.0
 170.0000    2161.5
 175.0000    2073.5
 180.0000    2028.0
 185.0000    2068.5
 190.0000    2050.0
 195.0000    2102.0
 200.0000    2184.0
 205.0000    2100.5
 210.0000    2144.0
 215.0000    2155.5
 220.0000    2290.0
 225.0000    2351.0
 230.0000    2388.5
 235.0000    2436.5
 240.0000    2484.0
 245.0000    2523.0
 250.0000    2569.5
 255.0000    2555.5
 260.0000    2500.5
 265.0000    2493.0
 270.0000    2539.5
 275.0000    2509.5
 280.0000    2569.5
 285.0000    2519.5
 290.0000    2526.5
 295.0000    2562.0
 300.0000    2554.0
 305.0000    2548.0
 310.0000    2539.5
 315.0000    2581.0
 320.0000    2514.5
 325.0000    2531.5
 330.0000    2564.5
 335.0000    2471.0
 340.0000    2537.5
 345.0000    2555.5
 350.0000    2423.5
 355.0000    2455.5
; (Data for Range number 4)
_DRIVE='PHI'
_STEPTIME=2.000000
_STEPSIZE=5.000000
_STEPMODE='C'
_START=0.000000
_THETA=29.850000
_2THETA=59.700001
_KHI=15.000000
_PHI=0.000000
_X=0.000000
_Y=0.000000
_Z=0.000000
_DIVERGENCE=3.000000
_ANTISCATTER=3.000000
_DETECTOR=1
; S.C.
_HV=687.000000
_GAIN=80.000000
_LLD=0.690000
_ULD=1.866000
_DETECTORSLIT='unkn'
_AUX1=0.000000
_AUX2=0.000000
_AUX3=0.000000
_TIMESTARTED=630.000000
_TEMP_RATE=0.000000
_TEMP_DELAY=0.000000
_KV=35
_MA=40
_RANGE_WL=1.788970
_3DPLANE=0
_2THETACPS
   0.0000    2517.5
   5.0000    2550.5
  10.0000    2544.0
  15.0000    2527.0
  20.0000    2516.5
  25.0000    2523.0
  30.0000    2546.5
  35.0000    2508.0
  40.0000    2521.5
  45.0000    2512.5
  50.0000    2477.0
  55.0000    2524.0
  60.0000    2458.0
  65.0000    2460.5
  70.0000    2426.5
  75.0000    2465.0
  80.0000    2519.0
  85.0000    2504.0
  90.0000    2533.5
  95.0000    2482.0
 100.0000    2465.0
 105.0000    2426.5
 110.0000    2529.0
 115.0000    2525.0
 120.0000    2483.0
 125.0000    2469.0
 130.0000    2411.0
 135.0000    2366.0
 140.0000    2348.0
 145.0000    2283.5
 150.0000    2196.5
 155.0000    2226.0
 160.0000    2185.5
 165.0000    2170.0
 170.0000    2166.5
 175.0000    2182.0
 180.0000    2214.0
 185.0000    2202.0
 190.0000    2127.0
 195.0000    2089.0
 200.0000    2249.5
 205.0000    2206.0
 210.0000    2241.5
 215.0000    2301.5
 220.0000    2378.0
 225.0000    2420.5
 230.0000    2449.0
 235.0000    2536.5
 240.0000    2552.5
 245.0000    2541.5
 250.0000    2529.5
 255.0000    2537.0
 260.0000    2517.5
 265.0000    2584.5
 270.0000    2635.5
 275.0000    2652.0
 280.0000    2639.0
 285.0000    2537.0
 290.0000    2539.0
 295.0000    2594.0
 300.0000    2549.5
 305.0000    2610.5
 310.0000    2599.0
 315.0000    2672.5
 320.0000    2597.0
 325.0000    2668.5
 330.0000    2563.5
 335.0000    2565.0
 340.0000    2622.0
 345.0000    2564.0
 350.0000    2474.5
 355.0000    2563.0
; (Data for Range number 5)
_DRIVE='PHI'
_STEPTIME=2.000000
_STEPSIZE=5.000000
_STEPMODE='C'
_START=0.000000
_THETA=29.850000
_2THETA=59.700001
_KHI=20.000000
_PHI=0.000000
_X=0.000000
_Y=0.000000
_Z=0.000000
_DIVERGENCE=3.000000
_ANTISCATTER=3.000000
_DETECTOR=1
; S.C.
_HV=687.000000
_GAIN=80.000000
_LLD=0.690000
_ULD=1.866000
_DETECTORSLIT='unkn'
_AUX1=0.000000
_AUX2=0.000000
_AUX3=0.000000
_TIMESTARTED=835.000000
_TEMP_RATE=0.000000
_TEMP_DELAY=0.000000
_KV=35
_MA=40
_RANGE_WL=1.788970
_3DPLANE=0
_2THETACPS
   0.0000    2686.5
   5.0000    2719.5
  10.0000    2754.5
  15.0000    2756.5
  20.0000    2620.0
  25.0000    2700.0
  30.0000    2741.0
  35.0000    2672.0
  40.0000    2718.0
  45.0000    2522.5
  50.0000    2595.5
  55.0000    2654.0
  60.0000    2568.5
  65.0000    2596.5
  70.0000    2534.0
  75.0000    2539.0
  80.0000    2505.5
  85.0000    2509.5
  90.0000    2588.0
  95.0000    2515.5
 100.0000    2552.0
 105.0000    2552.5
 110.0000    2580.0
 115.0000    2539.0
 120.0000    2596.5
 125.0000    2494.5
 130.0000    2436.5
 135.0000    2439.0
 140.0000    2401.5
 145.0000    2393.0
 150.0000    2390.0
 155.0000    2409.5
 160.0000    2423.5
 165.0000    2320.5
 170.0000    2338.0
 175.0000    2365.0
 180.0000    2387.0
 185.0000    2373.5
 190.0000    2418.5
 195.0000    2413.5
 200.0000    2318.0
 205.0000    2392.5
 210.0000    2404.5
 215.0000    2417.0
 220.0000    2472.5
 225.0000    2514.5
 230.0000    2511.5
 235.0000    2559.5
 240.0000    2619.5
 245.0000    2667.0
 250.0000    2707.0
 255.0000    2649.5
 260.0000    2627.0
 265.0000    2618.0
 270.0000    2601.5
 275.0000    2612.0
 280.0000    2647.5
 285.0000    2662.5
 290.0000    2649.0
 295.0000    2533.0
 300.0000    2683.5
 305.0000    2678.0
 310.0000    2699.5
 315.0000    2783.0
 320.0000    2832.0
 325.0000    2735.5
 330.0000    2825.5
 335.0000    2769.0
 340.0000    2782.5
 345.0000    2739.0
 350.0000    2684.0
 355.0000    2751.5
; (Data for Range number 6)
_DRIVE='PHI'
_STEPTIME=2.000000
_STEPSIZE=5.000000
_STEPMODE='C'
_START=0.000000
_THETA=29.850000
_2THETA=59.700001
_KHI=25.000000
_PHI=0.000000
_X=0.000000
_Y=0.000000
_Z=0.000000
_DIVERGENCE=3.000000
_ANTISCATTER=3.000000
_DETECTOR=1
; S.C.
_HV=687.000000
_GAIN=80.000000
_LLD=0.690000
_ULD=1.866000
_DETECTORSLIT='unkn'
_AUX1=0.000000
_AUX2=0.000000
_AUX3=0.000000
_TIMESTARTED=1040.000000
_TEMP_RATE=0.000000
_TEMP_DELAY=0.000000
_KV=35
_MA=40
_RANGE_WL=1.788970
_3DPLANE=0
_2THETACPS
   0.0000    2954.5
   5.0000    3065.5
  10.0000    3050.5
  15.0000    2989.5
  20.0000    2956.0
  25.0000    2901.5
  30.0000    2869.5
  35.0000    2895.5
  40.0000    2747.5
  45.0000    2783.5
  50.0000    2669.5
  55.0000    2760.5
  60.0000    2707.5
  65.0000    2665.5
  70.0000    2577.0
  75.0000    2565.5
  80.0000    2580.0
  85.0000    2627.5
  90.0000    2554.5
  95.0000    2561.0
 100.0000    2523.0
 105.0000    2650.0
 110.0000    2575.5
 115.0000    2621.5
 120.0000    2610.0
 125.0000    2646.0
 130.0000    2611.5
 135.0000    2603.0
 140.0000    2607.0
 145.0000    2518.0
 150.0000    2579.0
 155.0000    2607.0
 160.0000    2577.0
 165.0000    2656.0
 170.0000    2601.5
 175.0000    2606.5
 180.0000    2601.0
 185.0000    2544.5
 190.0000    2577.0
 195.0000    2642.5
 200.0000    2594.5
 205.0000    2605.5
 210.0000    2558.5
 215.0000    2592.5
 220.0000    2620.5
 225.0000    2724.0
 230.0000    2714.5
 235.0000    2729.0
 240.0000    2715.5
 245.0000    2701.0
 250.0000    2710.0
 255.0000    2665.5
 260.0000    2654.0
 265.0000    2664.5
 270.0000    2726.0
 275.0000    2728.0
 280.0000    2749.0
 285.0000    2746.0
 290.0000    2768.5
 295.0000    2790.5
 300.0000    2708.0
 305.0000    2901.0
 310.0000    2827.0
 315.0000    2864.0
 320.0000    2917.0
 325.0000    2997.5
 330.0000    2951.5
 335.0000    2958.0
 340.0000    3003.0
 345.0000    3065.5
 350.0000    2893.5
 355.0000    3014.5
; (Data for Range number 7)
_DRIVE='PHI'
_STEPTIME=2.000000
_STEPSIZE=5.000000
_STEPMODE='C'
_START=0.000000
_THETA=29.850000
_2THETA=59.700001
_KHI=30.000000
_PHI=0.000000
_X=0.000000
_Y=0.000000
_Z=0.000000
_DIVERGENCE=3.000000
_ANTISCATTER=3.000000
_DETECTOR=1
; S.C.
_HV=687.000000
_GAIN=80.000000
_LLD=0.690000
_ULD=1.866000
_DETECTORSLIT='unkn'
_AUX1=0.000000
_AUX2=0.000000
_AUX3=0.000000
_TIMESTARTED=1245.000000
_TEMP_RATE=0.000000
_TEMP_DELAY=0.000000
_KV=35
_MA=40
_RANGE_WL=1.788970
_3DPLANE=0
_2THETACPS
   0.0000    3015.5
   5.0000    3051.5
  10.0000    3114.5
  15.0000    3073.5
  20.0000    3066.5
  25.0000    3048.0
  30.0000    2992.0
  35.0000    3015.5
  40.0000    2924.5
  45.0000    2928.5
  50.0000    2790.0
  55.0000    2819.0
  60.0000    2713.5
  65.0000    2790.5
  70.0000    2720.0
  75.0000    2675.0
  80.0000    2637.5
  85.0000    2673.5
  90.0000    2677.5
  95.0000    2640.0
 100.0000    2687.5
 105.0000    2611.5
 110.0000    2733.0
 115.0000    2660.5
 120.0000    2691.0
 125.0000    2722.0
 130.0000    2687.0
 135.0000    2685.0
 140.0000    2667.5
 145.0000    2716.5
 150.0000    2620.0
 155.0000    2636.0
 160.0000    2607.5
 165.0000    2626.5
 170.0000    2670.0
 175.0000    2579.5
 180.0000    2650.5
 185.0000    2603.5
 190.0000    2619.0
 195.0000    2663.0
 200.0000    2654.0
 205.0000    2691.0
 210.0000    2781.0
 215.0000    2803.0
 220.0000    2887.5
 225.0000    2945.5
 230.0000    2892.5
 235.0000    2871.5
 240.0000    2813.5
 245.0000    2802.0
 250.0000    2801.0
 255.0000    2772.0
 260.0000    2800.5
 265.0000    2856.0
 270.0000    2758.5
 275.0000    2843.5
 280.0000    2723.0
 285.0000    2812.5
 290.0000    2871.5
 295.0000    2840.5
 300.0000    2908.5
 305.0000    3003.0
 310.0000    3014.5
 315.0000    3116.0
 320.0000    3093.5
 325.0000    3108.5
 330.0000    3117.5
 335.0000    3152.5
 340.0000    3165.5
 345.0000    3111.5
 350.0000    3116.5
 355.0000    3092.5
; (Data for Range number 8)
_DRIVE='PHI'
_STEPTIME=2.000000
_STEPSIZE=5.000000
_STEPMODE='C'
_START=0.000000
_THETA=29.850000
_2THETA=59.700001
_KHI=35.000000
_PHI=0.000000
_X=0.000000
_Y=0.000000
_Z=0.000000
_DIVERGENCE=3.000000
_ANTISCATTER=3.000000
_DETECTOR=1
; S.C.
_HV=687.000000
_GAIN=80.000000
_LLD=0.690000
_ULD=1.866000
_DETECTORSLIT='unkn'
_AUX1=0.000000
_AUX2=0.000000
_AUX3=0.000000
_TIMESTARTED=1450.000000
_TEMP_RATE=0.000000
_TEMP_DELAY=0.000000
_KV=35
_MA=40
_RANGE_WL=1.788970
_3DPLANE=0
_2THETACPS
   0.0000    2921.0
   5.0000    2934.5
  10.0000    2892.0
  15.0000    2923.5
  20.0000    2997.0
  25.0000    3092.5
  30.0000    3005.5
  35.0000    3042.0
  40.0000    3064.0
  45.0000    3012.5
  50.0000    2946.5
  55.0000    2922.0
  60.0000    2884.0
  65.0000    2789.0
  70.0000    2792.0
  75.0000    2707.5
  80.0000    2688.5
  85.0000    2663.0
  90.0000    2702.0
  95.0000    2698.0
 100.0000    2716.5
 105.0000    2709.0
 110.0000    2690.5
 115.0000    2764.0
 120.0000    2727.5
 125.0000    2689.5
 130.0000    2661.5
 135.0000    2726.0
 140.0000    2649.0
 145.0000    2562.0
 150.0000    2511.0
 155.0000    2587.5
 160.0000    2486.5
 165.0000    2454.5
 170.0000    2382.5
 175.0000    2384.0
 180.0000    2367.5
 185.0000    2357.0
 190.0000    2463.5
 195.0000    2455.0
 200.0000    2565.0
 205.0000    2650.0
 210.0000    2788.5
 215.0000    2771.0
 220.0000    2889.5
 225.0000    3007.0
 230.0000    3070.5
 235.0000    2965.0
 240.0000    2936.0
 245.0000    2944.0
 250.0000    2867.0
 255.0000    2882.0
 260.0000    2870.0
 265.0000    2887.0
 270.0000    2862.0
 275.0000    2833.0
 280.0000    2830.0
 285.0000    2860.5
 290.0000    2944.0
 295.0000    3001.0
 300.0000    3033.0
 305.0000    3164.0
 310.0000    3164.5
 315.0000    3115.0
 320.0000    3082.0
 325.0000    3058.5
 330.0000    3056.0
 335.0000    3024.5
 340.0000    2979.0
 345.0000    2943.0
 350.0000    2897.0
 355.0000    2888.0
; (Data for Range number 9)
_DRIVE='PHI'
_STEPTIME=2.000000
_STEPSIZE=5.000000
_STEPMODE='C'
_START=0.000000
_THETA=29.850000
_2THETA=59.700001
_KHI=40.000000
_PHI=0.000000
_X=0.000000
_Y=0.000000
_Z=0.000000
_DIVERGENCE=3.000000
_ANTISCATTER=3.000000
_DETECTOR=1
; S.C.
_HV=687.000000
_GAIN=80.000000
_LLD=0.690000
_ULD=1.866000
_DETECTORSLIT='unkn'
_AUX1=0.000000
_AUX2=0.000000
_AUX3=0.000000
_TIMESTARTED=1655.000000
_TEMP_RATE=0.000000
_TEMP_DELAY=0.000000
_KV=35
_MA=40
_RANGE_WL=1.788970
_3DPLANE=0
_2THETACPS
   0.0000    2554.5
   5.0000    2557.5
  10.0000    2634.0
  15.0000    2685.0
  20.0000    2891.0
  25.0000    2857.0
  30.0000    2894.0
  35.0000    3046.0
  40.0000    3071.5
  45.0000    3031.5
  50.0000    3026.0
  55.0000    3043.5
  60.0000    2954.0
  65.0000    2883.0
  70.0000    2782.0
  75.0000    2812.0
  80.0000    2700.0
  85.0000    2636.5
  90.0000    2733.5
  95.0000    2737.0
 100.0000    2816.0
 105.0000    2726.5
 110.0000    2785.5
 115.0000    2783.5
 120.0000    2725.5
 125.0000    2711.0
 130.0000    2633.5
 135.0000    2565.5
 140.0000    2488.0
 145.0000    2426.5
 150.0000    2330.0
 155.0000    2290.0
 160.0000    2206.5
 165.0000    2188.0
 170.0000    2115.5
 175.0000    2126.0
 180.0000    2140.0
 185.0000    2128.0
 190.0000    2186.5
 195.0000    2268.0
 200.0000    2394.5
 205.0000    2415.0
 210.0000    2639.5
 215.0000    2784.0
 220.0000    2873.5
 225.0000    2968.0
 230.0000    3035.5
 235.0000    3048.5
 240.0000    3040.0
 245.0000    2939.0
 250.0000    2852.0
 255.0000    2828.0
 260.0000    2907.0
 265.0000    2827.5
 270.0000    2874.5
 275.0000    2854.5
 280.0000    2893.5
 285.0000    2944.5
 290.0000    2960.5
 295.0000    3031.5
 300.0000    3100.5
 305.0000    3128.0
 310.0000    3049.0
 315.0000    2985.5
 320.0000    2916.5
 325.0000    2845.5
 330.0000    2792.5
 335.0000    2753.0
 340.0000    2626.0
 345.0000    2614.0
 350.0000    2551.5
 355.0000    2537.5
; (Data for Range number 10)
_DRIVE='PHI'
_STEPTIME=2.000000
_STEPSIZE=5.000000
_STEPMODE='C'
_START=0.000000
_THETA=29.850000
_2THETA=59.700001
_KHI=45.000000
_PHI=0.000000
_X=0.000000
_Y=0.000000
_Z=0.000000
_DIVERGENCE=3.000000
_ANTISCATTER=3.000000
_DETECTOR=1
; S.C.
_HV=687.000000
_GAIN=80.000000
_LLD=0.690000
_ULD=1.866000
_DETECTORSLIT='unkn'
_AUX1=0.000000
_AUX2=0.000000
_AUX3=0.000000
_TIMESTARTED=1860.000000
_TEMP_RATE=0.000000
_TEMP_DELAY=0.000000
_KV=35
_MA=40
_RANGE_WL=1.788970
_3DPLANE=0
_2THETACPS
   0.0000    2433.5
   5.0000    2404.0
  10.0000    2456.0
  15.0000    2470.0
  20.0000    2588.0
  25.0000    2691.0
  30.0000    2760.5
  35.0000    2825.5
  40.0000    2892.0
  45.0000    2909.0
  50.0000    2982.5
  55.0000    2968.0
  60.0000    2878.0
  65.0000    2832.0
  70.0000    2793.5
  75.0000    2778.0
  80.0000    2719.5
  85.0000    2777.0
  90.0000    2715.0
  95.0000    2676.0
 100.0000    2726.5
 105.0000    2774.5
 110.0000    2701.5
 115.0000    2763.0
 120.0000    2623.0
 125.0000    2591.0
 130.0000    2551.5
 135.0000    2416.5
 140.0000    2335.5
 145.0000    2290.5
 150.0000    2166.0
 155.0000    2101.0
 160.0000    2050.0
 165.0000    1996.5
 170.0000    1976.5
 175.0000    1911.0
 180.0000    1932.5
 185.0000    1931.5
 190.0000    1995.0
 195.0000    2093.0
 200.0000    2146.5
 205.0000    2271.5
 210.0000    2404.0
 215.0000    2626.5
 220.0000    2718.5
 225.0000    2929.0
 230.0000    3025.5
 235.0000    3029.5
 240.0000    3060.5
 245.0000    2954.5
 250.0000    2890.0
 255.0000    2854.5
 260.0000    2885.5
 265.0000    2809.5
 270.0000    2837.5
 275.0000    2831.0
 280.0000    2899.5
 285.0000    2872.5
 290.0000    2952.0
 295.0000    3074.0
 300.0000    3006.5
 305.0000    2964.5
 310.0000    2851.5
 315.0000    2732.5
 320.0000    2667.0
 325.0000    2632.0
 330.0000    2547.5
 335.0000    2443.5
 340.0000    2348.5
 345.0000    2327.0
 350.0000    2373.5
 355.0000    2375.5
; (Data for Range number 11)
_DRIVE='PHI'
_STEPTIME=2.000000
_STEPSIZE=5.000000
_STEPMODE='C'
_START=0.000000
_THETA=29.850000
_2THETA=59.700001
_KHI=50.000000
_PHI=0.000000
_X=0.000000
_Y=0.000000
_Z=0.000000
_DIVERGENCE=3.000000
_ANTISCATTER=3.000000
_DETECTOR=1
; S.C.
_HV=687.000000
_GAIN=80.000000
_LLD=0.690000
_ULD=1.866000
_DETECTORSLIT='unkn'
_AUX1=0.000000
_AUX2=0.000000
_AUX3=0.000000
_TIMESTARTED=2065.000000
_TEMP_RATE=0.000000
_TEMP_DELAY=0.000000
_KV=35
_MA=40
_RANGE_WL=1.788970
_3DPLANE=0
_2THETACPS
   0.0000    2174.5
   5.0000    2234.5
  10.0000    2282.5
  15.0000    2313.0
  20.0000    2467.0
  25.0000    2463.0
  30.0000    2603.5
  35.0000    2640.5
  40.0000    2744.0
  45.0000    2830.0
  50.0000    2915.0
  55.0000    2857.0
  60.0000    2813.0
  65.0000    2792.0
  70.0000    2738.0
  75.0000    2665.0
  80.0000    2725.0
  85.0000    2653.0
  90.0000    2571.0
  95.0000    2640.5
 100.0000    2639.5
 105.0000    2642.5
 110.0000    2630.0
 115.0000    2487.5
 120.0000    2515.0
 125.0000    2444.5
 130.0000    2280.0
 135.0000    2342.5
 140.0000    2108.0
 145.0000    2101.0
 150.0000    1956.0
 155.0000    1919.0
 160.0000    1909.0
 165.0000    1816.5
 170.0000    1816.0
 175.0000    1785.5
 180.0000    1869.0
 185.0000    1903.5
 190.0000    1898.0
 195.0000    1905.0
 200.0000    2091.0
 205.0000    2122.0
 210.0000    2267.5
 215.0000    2424.5
 220.0000    2636.5
 225.0000    2736.0
 230.0000    2950.5
 235.0000    2861.5
 240.0000    2855.0
 245.0000    2792.5
 250.0000    2789.5
 255.0000    2756.0
 260.0000    2751.5
 265.0000    2665.0
 270.0000    2753.5
 275.0000    2727.0
 280.0000    2804.0
 285.0000    2789.5
 290.0000    2769.5
 295.0000    2785.0
 300.0000    2737.0
 305.0000    2750.0
 310.0000    2525.0
 315.0000    2523.5
 320.0000    2359.5
 325.0000    2305.0
 330.0000    2206.5
 335.0000    2247.5
 340.0000    2193.5
 345.0000    2122.0
 350.0000    2163.0
 355.0000    2176.0
; (Data for Range number 12)
_DRIVE='PHI'
_STEPTIME=2.000000
_STEPSIZE=5.000000
_STEPMODE='C'
_START=0.000000
_THETA=29.850000
_2THETA=59.700001
_KHI=55.000000
_PHI=0.000000
_X=0.000000
_Y=0.000000
_Z=0.000000
_DIVERGENCE=3.000000
_ANTISCATTER=3.000000
_DETECTOR=1
; S.C.
_HV=687.000000
_GAIN=80.000000
_LLD=0.690000
_ULD=1.866000
_DETECTORSLIT='unkn'
_AUX1=0.000000
_AUX2=0.000000
_AUX3=0.000000
_TIMESTARTED=2270.000000
_TEMP_RATE=0.000000
_TEMP_DELAY=0.000000
_KV=35
_MA=40
_RANGE_WL=1.788970
_3DPLANE=0
_2THETACPS
   0.0000    2032.5
   5.0000    2065.0
  10.0000    2150.5
  15.0000    2271.5
  20.0000    2320.5
  25.0000    2417.5
  30.0000    2504.0
  35.0000    2589.0
  40.0000    2685.5
  45.0000    2678.0
  50.0000    2697.5
  55.0000    2766.5
  60.0000    2654.5
  65.0000    2593.0
  70.0000    2644.0
  75.0000    2571.5
  80.0000    2592.5
  85.0000    2543.5
  90.0000    2572.5
  95.0000    2564.0
 100.0000    2571.0
 105.0000    2491.5
 110.0000    2423.5
 115.0000    2406.0
 120.0000    2320.5
 125.0000    2199.0
 130.0000    2088.0
 135.0000    2092.0
 140.0000    1943.0
 145.0000    1885.5
 150.0000    1950.5
 155.0000    1784.5
 160.0000    1797.0
 165.0000    1730.5
 170.0000    1682.5
 175.0000    1751.5
 180.0000    1727.5
 185.0000    1796.5
 190.0000    1855.5
 195.0000    1876.5
 200.0000    1961.5
 205.0000    2044.0
 210.0000    2196.0
 215.0000    2347.5
 220.0000    2499.0
 225.0000    2641.5
 230.0000    2746.5
 235.0000    2791.0
 240.0000    2741.0
 245.0000    2770.0
 250.0000    2732.5
 255.0000    2714.5
 260.0000    2626.5
 265.0000    2662.5
 270.0000    2653.5
 275.0000    2689.5
 280.0000    2645.5
 285.0000    2666.0
 290.0000    2623.0
 295.0000    2542.0
 300.0000    2473.5
 305.0000    2433.0
 310.0000    2331.5
 315.0000    2251.0
 320.0000    2151.0
 325.0000    2092.0
 330.0000    2034.0
 335.0000    1970.5
 340.0000    2005.0
 345.0000    1976.5
 350.0000    1966.0
 355.0000    2000.5
; (Data for Range number 13)
_DRIVE='PHI'
_STEPTIME=2.000000
_STEPSIZE=5.000000
_STEPMODE='C'
_START=0.000000
_THETA=29.850000
_2THETA=59.700001
_KHI=60.000000
_PHI=0.000000
_X=0.000000
_Y=0.000000
_Z=0.000000
_DIVERGENCE=3.000000
_ANTISCATTER=3.000000
_DETECTOR=1
; S.C.
_HV=687.000000
_GAIN=80.000000
_LLD=0.690000
_ULD=1.866000
_DETECTORSLIT='unkn'
_AUX1=0.000000
_AUX2=0.000000
_AUX3=0.000000
_TIMESTARTED=2475.000000
_TEMP_RATE=0.000000
_TEMP_DELAY=0.000000
_KV=35
_MA=40
_RANGE_WL=1.788970
_3DPLANE=0
_2THETACPS
   0.0000    1865.0
   5.0000    1947.0
  10.0000    1980.0
  15.0000    2055.0
  20.0000    2175.0
  25.0000    2256.0
  30.0000    2445.5
  35.0000    2461.0
  40.0000    2571.0
  45.0000    2541.5
  50.0000    2553.5
  55.0000    2579.0
  60.0000    2561.0
  65.0000    2485.0
  70.0000    2451.0
  75.0000    2430.5
  80.0000    2371.0
  85.0000    2508.5
  90.0000    2376.0
  95.0000    2374.0
 100.0000    2379.5
 105.0000    2263.0
 110.0000    2227.0
 115.0000    2130.5
 120.0000    2089.5
 125.0000    1986.0
 130.0000    1909.5
 135.0000    1842.0
 140.0000    1783.0
 145.0000    1698.0
 150.0000    1708.0
 155.0000    1705.0
 160.0000    1630.5
 165.0000    1624.0
 170.0000    1599.0
 175.0000    1645.5
 180.0000    1663.0
 185.0000    1711.0
 190.0000    1725.0
 195.0000    1813.5
 200.0000    1865.0
 205.0000    1902.0
 210.0000    2064.5
 215.0000    2236.5
 220.0000    2331.5
 225.0000    2516.0
 230.0000    2601.0
 235.0000    2581.5
 240.0000    2590.5
 245.0000    2594.5
 250.0000    2541.5
 255.0000    2475.5
 260.0000    2500.0
 265.0000    2626.0
 270.0000    2524.5
 275.0000    2537.5
 280.0000    2489.0
 285.0000    2450.0
 290.0000    2376.0
 295.0000    2250.5
 300.0000    2137.5
 305.0000    2097.5
 310.0000    2008.0
 315.0000    1954.0
 320.0000    1839.0
 325.0000    1829.0
 330.0000    1764.0
 335.0000    1732.0
 340.0000    1755.0
 345.0000    1756.0
 350.0000    1729.5
 355.0000    1823.5
; (Data for Range number 14)
_DRIVE='PHI'
_STEPTIME=2.000000
_STEPSIZE=5.000000
_STEPMODE='C'
_START=0.000000
_THETA=29.850000
_2THETA=59.700001
_KHI=65.000000
_PHI=0.000000
_X=0.000000
_Y=0.000000
_Z=0.000000
_DIVERGENCE=3.000000
_ANTISCATTER=3.000000
_DETECTOR=1
; S.C.
_HV=687.000000
_GAIN=80.000000
_LLD=0.690000
_ULD=1.866000
_DETECTORSLIT='unkn'
_AUX1=0.000000
_AUX2=0.000000
_AUX3=0.000000
_TIMESTARTED=2680.000000
_TEMP_RATE=0.000000
_TEMP_DELAY=0.000000
_KV=35
_MA=40
_RANGE_WL=1.788970
_3DPLANE=0
_2THETACPS
   0.0000    1516.0
   5.0000    1615.5
  10.0000    1719.0
  15.0000    1827.0
  20.0000    1939.5
  25.0000    2093.5
  30.0000    2259.0
  35.0000    2342.5
  40.0000    2420.0
  45.0000    2408.5
  50.0000    2473.0
  55.0000    2420.5
  60.0000    2364.0
  65.0000    2314.0
  70.0000    2236.0
  75.0000    2303.0
  80.0000    2213.0
  85.0000    2264.0
  90.0000    2303.5
  95.0000    2203.5
 100.0000    2117.5
 105.0000    2068.0
 110.0000    1967.5
 115.0000    1856.5
 120.0000    1752.5
 125.0000    1697.0
 130.0000    1624.5
 135.0000    1567.5
 140.0000    1505.0
 145.0000    1481.5
 150.0000    1461.0
 155.0000    1482.0
 160.0000    1411.0
 165.0000    1382.0
 170.0000    1397.5
 175.0000    1469.5
 180.0000    1433.0
 185.0000    1513.0
 190.0000    1578.0
 195.0000    1659.5
 200.0000    1755.0
 205.0000    1889.5
 210.0000    1948.0
 215.0000    2031.5
 220.0000    2205.0
 225.0000    2334.0
 230.0000    2381.5
 235.0000    2401.0
 240.0000    2469.0
 245.0000    2386.0
 250.0000    2374.5
 255.0000    2326.0
 260.0000    2441.0
 265.0000    2471.5
 270.0000    2486.5
 275.0000    2438.0
 280.0000    2281.5
 285.0000    2116.5
 290.0000    2084.5
 295.0000    1992.5
 300.0000    1800.0
 305.0000    1783.0
 310.0000    1644.5
 315.0000    1681.0
 320.0000    1575.5
 325.0000    1533.5
 330.0000    1495.0
 335.0000    1501.5
 340.0000    1501.0
 345.0000    1479.5
 350.0000    1515.0
 355.0000    1544.0
; (Data for Range number 15)
_DRIVE='PHI'
_STEPTIME=2.000000
_STEPSIZE=5.000000
_STEPMODE='C'
_START=0.000000
_THETA=29.850000
_2THETA=59.700001
_KHI=70.000000
_PHI=0.000000
_X=0.000000
_Y=0.000000
_Z=0.000000
_DIVERGENCE=3.000000
_ANTISCATTER=3.000000
_DETECTOR=1
; S.C.
_HV=687.000000
_GAIN=80.000000
_LLD=0.690000
_ULD=1.866000
_DETECTORSLIT='unkn'
_AUX1=0.000000
_AUX2=0.000000
_AUX3=0.000000
_TIMESTARTED=2885.000000
_TEMP_RATE=0.000000
_TEMP_DELAY=0.000000
_KV=35
_MA=40
_RANGE_WL=1.788970
_3DPLANE=0
_2THETACPS
   0.0000    1265.0
   5.0000    1359.0
  10.0000    1409.0
  15.0000    1505.5
  20.0000    1685.0
  25.0000    1840.5
  30.0000    2050.5
  35.0000    2035.0
  40.0000    2174.0
  45.0000    2192.0
  50.0000    2184.5
  55.0000    2131.0
  60.0000    2118.5
  65.0000    2044.0
  70.0000    2058.5
  75.0000    2057.5
  80.0000    2111.5
  85.0000    2035.5
  90.0000    2032.5
  95.0000    2014.5
 100.0000    1886.5
 105.0000    1809.5
 110.0000    1678.0
 115.0000    1581.5
 120.0000    1438.0
 125.0000    1386.5
 130.0000    1300.5
 135.0000    1265.0
 140.0000    1244.5
 145.0000    1219.0
 150.0000    1209.0
 155.0000    1135.0
 160.0000    1154.0
 165.0000    1113.0
 170.0000    1154.5
 175.0000    1226.0
 180.0000    1317.5
 185.0000    1294.5
 190.0000    1279.0
 195.0000    1423.0
 200.0000    1546.0
 205.0000    1692.0
 210.0000    1711.0
 215.0000    1878.0
 220.0000    1972.5
 225.0000    2073.5
 230.0000    2156.5
 235.0000    2061.5
 240.0000    2063.5
 245.0000    2093.5
 250.0000    2063.5
 255.0000    2121.0
 260.0000    2141.0
 265.0000    2239.0
 270.0000    2214.5
 275.0000    2143.5
 280.0000    1965.0
 285.0000    1884.0
 290.0000    1741.0
 295.0000    1552.0
 300.0000    1503.5
 305.0000    1385.0
 310.0000    1411.5
 315.0000    1341.0
 320.0000    1234.0
 325.0000    1275.0
 330.0000    1208.0
 335.0000    1223.5
 340.0000    1233.5
 345.0000    1231.5
 350.0000    1264.5
 355.0000    1276.5
; (Data for Range number 16)
_DRIVE='PHI'
_STEPTIME=2.000000
_STEPSIZE=5.000000
_STEPMODE='C'
_START=0.000000
_THETA=29.850000
_2THETA=59.700001
_KHI=75.000000
_PHI=0.000000
_X=0.000000
_Y=0.000000
_Z=0.000000
_DIVERGENCE=3.000000
_ANTISCATTER=3.000000
_DETECTOR=1
; S.C.
_HV=687.000000
_GAIN=80.000000
_LLD=0.690000
_ULD=1.866000
_DETECTORSLIT='unkn'
_AUX1=0.000000
_AUX2=0.000000
_AUX3=0.000000
_TIMESTARTED=3090.000000
_TEMP_RATE=0.000000
_TEMP_DELAY=0.000000
_KV=35
_MA=40
_RANGE_WL=1.788970
_3DPLANE=0
_2THETACPS
   0.0000    998.50
   5.0000    1054.5
  10.0000    1167.0
  15.0000    1222.5
  20.0000    1328.5
  25.0000    1469.0
  30.0000    1591.0
  35.0000    1738.5
  40.0000    1833.0
  45.0000    1834.0
  50.0000    1768.5
  55.0000    1697.0
  60.0000    1711.0
  65.0000    1732.5
  70.0000    1724.5
  75.0000    1750.5
  80.0000    1757.0
  85.0000    1765.5
  90.0000    1814.0
  95.0000    1756.5
 100.0000    1654.5
 105.0000    1536.0
 110.0000    1415.5
 115.0000    1241.5
 120.0000    1069.5
 125.0000    1042.5
 130.0000    1007.0
 135.0000    976.00
 140.0000    953.00
 145.0000    890.00
 150.0000    918.50
 155.0000    872.50
 160.0000    903.00
 165.0000    883.00
 170.0000    903.00
 175.0000    936.00
 180.0000    950.00
 185.0000    990.00
 190.0000    1065.0
 195.0000    1150.0
 200.0000    1247.5
 205.0000    1327.0
 210.0000    1391.5
 215.0000    1470.0
 220.0000    1517.0
 225.0000    1565.0
 230.0000    1623.0
 235.0000    1683.5
 240.0000    1660.0
 245.0000    1639.5
 250.0000    1643.5
 255.0000    1733.5
 260.0000    1861.0
 265.0000    1891.5
 270.0000    1892.5
 275.0000    1751.0
 280.0000    1620.0
 285.0000    1466.5
 290.0000    1346.0
 295.0000    1256.5
 300.0000    1123.5
 305.0000    1085.0
 310.0000    1059.5
 315.0000    1028.5
 320.0000    997.50
 325.0000    950.00
 330.0000    978.50
 335.0000    964.50
 340.0000    937.50
 345.0000    965.00
 350.0000    983.00
 355.0000    979.00
; (Data for Range number 17)
_DRIVE='PHI'
_STEPTIME=2.000000
_STEPSIZE=5.000000
_STEPMODE='C'
_START=0.000000
_THETA=29.850000
_2THETA=59.700001
_KHI=80.000000
_PHI=0.000000
_X=0.000000
_Y=0.000000
_Z=0.000000
_DIVERGENCE=3.000000
_ANTISCATTER=3.000000
_DETECTOR=1
; S.C.
_HV=687.000000
_GAIN=80.000000
_LLD=0.690000
_ULD=1.866000
_DETECTORSLIT='unkn'
_AUX1=0.000000
_AUX2=0.000000
_AUX3=0.000000
_TIMESTARTED=3295.000000
_TEMP_RATE=0.000000
_TEMP_DELAY=0.000000
_KV=35
_MA=40
_RANGE_WL=1.788970
_3DPLANE=0
_2THETACPS
   0.0000    748.00
   5.0000    755.00
  10.0000    822.50
  15.0000    869.50
  20.0000    946.00
  25.0000    1040.5
  30.0000    1177.5
  35.0000    1198.0
  40.0000    1271.5
  45.0000    1264.0
  50.0000    1245.5
  55.0000    1215.5
  60.0000    1245.0
  65.0000    1234.0
  70.0000    1203.0
  75.0000    1227.5
  80.0000    1264.5
  85.0000    1401.0
  90.0000    1505.0
  95.0000    1477.5
 100.0000    1285.0
 105.0000    1172.5
 110.0000    1049.5
 115.0000    898.50
 120.0000    730.50
 125.0000    719.50
 130.0000    684.00
 135.0000    666.50
 140.0000    622.00
 145.0000    627.00
 150.0000    641.00
 155.0000    608.50
 160.0000    639.50
 165.0000    636.50
 170.0000    645.50
 175.0000    675.50
 180.0000    679.50
 185.0000    678.50
 190.0000    753.50
 195.0000    800.00
 200.0000    884.50
 205.0000    943.00
 210.0000    953.50
 215.0000    1011.5
 220.0000    1053.5
 225.0000    1102.5
 230.0000    1136.0
 235.0000    1158.5
 240.0000    1104.5
 245.0000    1170.5
 250.0000    1163.5
 255.0000    1269.0
 260.0000    1347.5
 265.0000    1374.5
 270.0000    1365.5
 275.0000    1249.0
 280.0000    1130.0
 285.0000    1055.0
 290.0000    963.50
 295.0000    879.00
 300.0000    785.50
 305.0000    748.50
 310.0000    703.00
 315.0000    737.50
 320.0000    690.50
 325.0000    662.50
 330.0000    617.50
 335.0000    679.50
 340.0000    663.00
 345.0000    675.00
 350.0000    667.50
 355.0000    691.00
; (Data for Range number 18)
_DRIVE='PHI'
_STEPTIME=10.000000
_STEPSIZE=5.000000
_STEPMODE='S'
_START=0.000000
_THETA=28.000000
_2THETA=56.000000
_KHI=0.000000
_PHI=0.000000
_X=0.000000
_Y=0.000000
_Z=0.000000
_DIVERGENCE=3.000000
_ANTISCATTER=3.000000
_DETECTOR=1
; S.C.
_HV=687.000000
_GAIN=80.000000
_LLD=0.690000
_ULD=1.866000
_DETECTORSLIT='unkn'
_AUX1=0.000000
_AUX2=0.000000
_AUX3=0.000000
_TIMESTARTED=3498.000000
_TEMP_RATE=0.000000
_TEMP_DELAY=0.000000
_KV=35
_MA=40
_RANGE_WL=1.788970
_3DPLANE=0
_2THETACPS
   0.0000    2167.1
; (Data for Range number 19)
_DRIVE='PHI'
_STEPTIME=10.000000
_STEPSIZE=5.000000
_STEPMODE='S'
_START=0.000000
_THETA=28.000000
_2THETA=56.000000
_KHI=5.000000
_PHI=0.000000
_X=0.000000
_Y=0.000000
_Z=0.000000
_DIVERGENCE=3.000000
_ANTISCATTER=3.000000
_DETECTOR=1
; S.C.
_HV=687.000000
_GAIN=80.000000
_LLD=0.690000
_ULD=1.866000
_DETECTORSLIT='unkn'
_AUX1=0.000000
_AUX2=0.000000
_AUX3=0.000000
_TIMESTARTED=3513.000000
_TEMP_RATE=0.000000
_TEMP_DELAY=0.000000
_KV=35
_MA=40
_RANGE_WL=1.788970
_3DPLANE=0
_2THETACPS
   0.0000    2156.0
; (Data for Range number 20)
_DRIVE='PHI'
_STEPTIME=10.000000
_STEPSIZE=5.000000
_STEPMODE='S'
_START=0.000000
_THETA=28.000000
_2THETA=56.000000
_KHI=10.000000
_PHI=0.000000
_X=0.000000
_Y=0.000000
_Z=0.000000
_DIVERGENCE=3.000000
_ANTISCATTER=3.000000
_DETECTOR=1
; S.C.
_HV=687.000000
_GAIN=80.000000
_LLD=0.690000
_ULD=1.866000
_DETECTORSLIT='unkn'
_AUX1=0.000000
_AUX2=0.000000
_AUX3=0.000000
_TIMESTARTED=3528.000000
_TEMP_RATE=0.000000
_TEMP_DELAY=0.000000
_KV=35
_MA=40
_RANGE_WL=1.788970
_3DPLANE=0
_2THETACPS
   0.0000    2158.4
; (Data for Range number 21)
_DRIVE='PHI'
_STEPTIME=10.000000
_STEPSIZE=5.000000
_STEPMODE='S'
_START=0.000000
_THETA=28.000000
_2THETA=56.000000
_KHI=15.000000
_PHI=0.000000
_X=0.000000
_Y=0.000000
_Z=0.000000
_DIVERGENCE=3.000000
_ANTISCATTER=3.000000
_DETECTOR=1
; S.C.
_HV=687.000000
_GAIN=80.000000
_LLD=0.690000
_ULD=1.866000
_DETECTORSLIT='unkn'
_AUX1=0.000000
_AUX2=0.000000
_AUX3=0.000000
_TIMESTARTED=3543.000000
_TEMP_RATE=0.000000
_TEMP_DELAY=0.000000
_KV=35
_MA=40
_RANGE_WL=1.788970
_3DPLANE=0
_2THETACPS
   0.0000    2188.8
; (Data for Range number 22)
_DRIVE='PHI'
_STEPTIME=10.000000
_STEPSIZE=5.000000
_STEPMODE='S'
_START=0.000000
_THETA=28.000000
_2THETA=56.000000
_KHI=20.000000
_PHI=0.000000
_X=0.000000
_Y=0.000000
_Z=0.000000
_DIVERGENCE=3.000000
_ANTISCATTER=3.000000
_DETECTOR=1
; S.C.
_HV=687.000000
_GAIN=80.000000
_LLD=0.690000
_ULD=1.866000
_DETECTORSLIT='unkn'
_AUX1=0.000000
_AUX2=0.000000
_AUX3=0.000000
_TIMESTARTED=3558.000000
_TEMP_RATE=0.000000
_TEMP_DELAY=0.000000
_KV=35
_MA=40
_RANGE_WL=1.788970
_3DPLANE=0
_2THETACPS
   0.0000    2209.9
; (Data for Range number 23)
_DRIVE='PHI'
_STEPTIME=10.000000
_STEPSIZE=5.000000
_STEPMODE='S'
_START=0.000000
_THETA=28.000000
_2THETA=56.000000
_KHI=25.000000
_PHI=0.000000
_X=0.000000
_Y=0.000000
_Z=0.000000
_DIVERGENCE=3.000000
_ANTISCATTER=3.000000
_DETECTOR=1
; S.C.
_HV=687.000000
_GAIN=80.000000
_LLD=0.690000
_ULD=1.866000
_DETECTORSLIT='unkn'
_AUX1=0.000000
_AUX2=0.000000
_AUX3=0.000000
_TIMESTARTED=3573.000000
_TEMP_RATE=0.000000
_TEMP_DELAY=0.000000
_KV=35
_MA=40
_RANGE_WL=1.788970
_3DPLANE=0
_2THETACPS
   0.0000    2246.0
; (Data for Range number 24)
_DRIVE='PHI'
_STEPTIME=10.000000
_STEPSIZE=5.000000
_STEPMODE='S'
_START=0.000000
_THETA=28.000000
_2THETA=56.000000
_KHI=30.000000
_PHI=0.000000
_X=0.000000
_Y=0.000000
_Z=0.000000
_DIVERGENCE=3.000000
_ANTISCATTER=3.000000
_DETECTOR=1
; S.C.
_HV=687.000000
_GAIN=80.000000
_LLD=0.690000
_ULD=1.866000
_DETECTORSLIT='unkn'
_AUX1=0.000000
_AUX2=0.000000
_AUX3=0.000000
_TIMESTARTED=3588.000000
_TEMP_RATE=0.000000
_TEMP_DELAY=0.000000
_KV=35
_MA=40
_RANGE_WL=1.788970
_3DPLANE=0
_2THETACPS
   0.0000    2284.3
; (Data for Range number 25)
_DRIVE='PHI'
_STEPTIME=10.000000
_STEPSIZE=5.000000
_STEPMODE='S'
_START=0.000000
_THETA=28.000000
_2THETA=56.000000
_KHI=35.000000
_PHI=0.000000
_X=0.000000
_Y=0.000000
_Z=0.000000
_DIVERGENCE=3.000000
_ANTISCATTER=3.000000
_DETECTOR=1
; S.C.
_HV=687.000000
_GAIN=80.000000
_LLD=0.690000
_ULD=1.866000
_DETECTORSLIT='unkn'
_AUX1=0.000000
_AUX2=0.000000
_AUX3=0.000000
_TIMESTARTED=3603.000000
_TEMP_RATE=0.000000
_TEMP_DELAY=0.000000
_KV=35
_MA=40
_RANGE_WL=1.788970
_3DPLANE=0
_2THETACPS
   0.0000    2232.4
; (Data for Range number 26)
_DRIVE='PHI'
_STEPTIME=10.000000
_STEPSIZE=5.000000
_STEPMODE='S'
_START=0.000000
_THETA=28.000000
_2THETA=56.000000
_KHI=40.000000
_PHI=0.000000
_X=0.000000
_Y=0.000000
_Z=0.000000
_DIVERGENCE=3.000000
_ANTISCATTER=3.000000
_DETECTOR=1
; S.C.
_HV=687.000000
_GAIN=80.000000
_LLD=0.690000
_ULD=1.866000
_DETECTORSLIT='unkn'
_AUX1=0.000000
_AUX2=0.000000
_AUX3=0.000000
_TIMESTARTED=3618.000000
_TEMP_RATE=0.000000
_TEMP_DELAY=0.000000
_KV=35
_MA=40
_RANGE_WL=1.788970
_3DPLANE=0
_2THETACPS
   0.0000    2154.9
; (Data for Range number 27)
_DRIVE='PHI'
_STEPTIME=10.000000
_STEPSIZE=5.000000
_STEPMODE='S'
_START=0.000000
_THETA=28.000000
_2THETA=56.000000
_KHI=45.000000
_PHI=0.000000
_X=0.000000
_Y=0.000000
_Z=0.000000
_DIVERGENCE=3.000000
_ANTISCATTER=3.000000
_DETECTOR=1
; S.C.
_HV=687.000000
_GAIN=80.000000
_LLD=0.690000
_ULD=1.866000
_DETECTORSLIT='unkn'
_AUX1=0.000000
_AUX2=0.000000
_AUX3=0.000000
_TIMESTARTED=3633.000000
_TEMP_RATE=0.000000
_TEMP_DELAY=0.000000
_KV=35
_MA=40
_RANGE_WL=1.788970
_3DPLANE=0
_2THETACPS
   0.0000    2085.6
; (Data for Range number 28)
_DRIVE='PHI'
_STEPTIME=10.000000
_STEPSIZE=5.000000
_STEPMODE='S'
_START=0.000000
_THETA=28.000000
_2THETA=56.000000
_KHI=50.000000
_PHI=0.000000
_X=0.000000
_Y=0.000000
_Z=0.000000
_DIVERGENCE=3.000000
_ANTISCATTER=3.000000
_DETECTOR=1
; S.C.
_HV=687.000000
_GAIN=80.000000
_LLD=0.690000
_ULD=1.866000
_DETECTORSLIT='unkn'
_AUX1=0.000000
_AUX2=0.000000
_AUX3=0.000000
_TIMESTARTED=3648.000000
_TEMP_RATE=0.000000
_TEMP_DELAY=0.000000
_KV=35
_MA=40
_RANGE_WL=1.788970
_3DPLANE=0
_2THETACPS
   0.0000    1942.9
; (Data for Range number 29)
_DRIVE='PHI'
_STEPTIME=10.000000
_STEPSIZE=5.000000
_STEPMODE='S'
_START=0.000000
_THETA=28.000000
_2THETA=56.000000
_KHI=55.000000
_PHI=0.000000
_X=0.000000
_Y=0.000000
_Z=0.000000
_DIVERGENCE=3.000000
_ANTISCATTER=3.000000
_DETECTOR=1
[...]
_TIMESTARTED=23219.000000
_TEMP_RATE=0.000000
_TEMP_DELAY=0.000000
_KV=35
_MA=40
_RANGE_WL=1.788970
_3DPLANE=0
_2THETACPS
   0.0000    2195.0
   5.0000    2367.5
  10.0000    2424.0
  15.0000    2441.5
  20.0000    2451.5
  25.0000    2450.5
  30.0000    2403.0
  35.0000    2394.5
  40.0000    2357.0
  45.0000    2393.0
  50.0000    2453.5
  55.0000    2473.5
  60.0000    2484.0
  65.0000    2371.0
  70.0000    2286.0
  75.0000    2271.5
  80.0000    2121.5
  85.0000    2067.5
  90.0000    1967.5
  95.0000    1921.5
 100.0000    1833.0
 105.0000    1711.0
 110.0000    1704.0
 115.0000    1625.0
 120.0000    1614.5
 125.0000    1562.5
 130.0000    1543.5
 135.0000    1539.5
 140.0000    1415.0
 145.0000    1411.0
 150.0000    1388.5
 155.0000    1403.0
 160.0000    1480.0
 165.0000    1648.0
 170.0000    1814.5
 175.0000    1992.0
 180.0000    2195.5
 185.0000    2292.5
 190.0000    2291.0
 195.0000    2454.5
 200.0000    2448.0
 205.0000    2453.5
 210.0000    2418.0
 215.0000    2415.5
 220.0000    2358.0
 225.0000    2455.0
 230.0000    2434.0
 235.0000    2459.0
 240.0000    2367.5
 245.0000    2206.5
 250.0000    2065.0
 255.0000    1931.5
 260.0000    2054.5
 265.0000    1963.0
 270.0000    1932.5
 275.0000    1924.0
 280.0000    1865.5
 285.0000    1791.5
 290.0000    1755.0
 295.0000    1683.0
 300.0000    1658.5
 305.0000    1620.0
 310.0000    1637.5
 315.0000    1548.0
 320.0000    1612.0
 325.0000    1513.0
 330.0000    1460.0
 335.0000    1540.0
 340.0000    1552.0
 345.0000    1714.5
 350.0000    1864.0
 355.0000    2015.5
; (Data for Range number 256)
_DRIVE='PHI'
_STEPTIME=10.000000
_STEPSIZE=5.000000
_STEPMODE='S'
_START=0.000000
_THETA=59.000000
_2THETA=118.000000
_KHI=0.000000
_PHI=0.000000
_X=0.000000
_Y=0.000000
_Z=0.000000
_DIVERGENCE=3.000000
_ANTISCATTER=3.000000
_DETECTOR=1
; S.C.
_HV=687.000000
_GAIN=80.000000
_LLD=0.690000
_ULD=1.866000
_DETECTORSLIT='unkn'
_AUX1=0.000000
_AUX2=0.000000
_AUX3=0.000000
_TIMESTARTED=23421.000000
_TEMP_RATE=0.000000
_TEMP_DELAY=0.000000
_KV=35
_MA=40
_RANGE_WL=1.788970
_3DPLANE=0
_2THETACPS
   0.0000    2220.2
; (Data for Range number 257)
_DRIVE='PHI'
_STEPTIME=10.000000
_STEPSIZE=5.000000
_STEPMODE='S'
_START=0.000000
_THETA=59.000000
_2THETA=118.000000
_KHI=5.000000
_PHI=0.000000
_X=0.000000
_Y=0.000000
_Z=0.000000
_DIVERGENCE=3.000000
_ANTISCATTER=3.000000
_DETECTOR=1
; S.C.
_HV=687.000000
_GAIN=80.000000
_LLD=0.690000
_ULD=1.866000
_DETECTORSLIT='unkn'
_AUX1=0.000000
_AUX2=0.000000
_AUX3=0.000000
_TIMESTARTED=23436.000000
_TEMP_RATE=0.000000
_TEMP_DELAY=0.000000
_KV=35
_MA=40
_RANGE_WL=1.788970
_3DPLANE=0
_2THETACPS
   0.0000    2188.7
; (Data for Range number 258)
_DRIVE='PHI'
_STEPTIME=10.000000
_STEPSIZE=5.000000
_STEPMODE='S'
_START=0.000000
_THETA=59.000000
_2THETA=118.000000
_KHI=10.000000
_PHI=0.000000
_X=0.000000
_Y=0.000000
_Z=0.000000
_DIVERGENCE=3.000000
_ANTISCATTER=3.000000
_DETECTOR=1
; S.C.
_HV=687.000000
_GAIN=80.000000
_LLD=0.690000
_ULD=1.866000
_DETECTORSLIT='unkn'
_AUX1=0.000000
_AUX2=0.000000
_AUX3=0.000000
_TIMESTARTED=23452.000000
_TEMP_RATE=0.000000
_TEMP_DELAY=0.000000
_KV=35
_MA=40
_RANGE_WL=1.788970
_3DPLANE=0
_2THETACPS
   0.0000    2196.9
; (Data for Range number 259)
_DRIVE='PHI'
_STEPTIME=10.000000
_STEPSIZE=5.000000
_STEPMODE='S'
_START=0.000000
_THETA=59.000000
_2THETA=118.000000
_KHI=15.000000
_PHI=0.000000
_X=0.000000
_Y=0.000000
_Z=0.000000
_DIVERGENCE=3.000000
_ANTISCATTER=3.000000
_DETECTOR=1
; S.C.
_HV=687.000000
_GAIN=80.000000
_LLD=0.690000
_ULD=1.866000
_DETECTORSLIT='unkn'
_AUX1=0.000000
_AUX2=0.000000
_AUX3=0.000000
_TIMESTARTED=23466.000000
_TEMP_RATE=0.000000
_TEMP_DELAY=0.000000
_KV=35
_MA=40
_RANGE_WL=1.788970
_3DPLANE=0
_2THETACPS
   0.0000    2197.5
; (Data for Range number 260)
_DRIVE='PHI'
_STEPTIME=10.000000
_STEPSIZE=5.000000
_STEPMODE='S'
_START=0.000000
_THETA=59.000000
_2THETA=118.000000
_KHI=20.000000
_PHI=0.000000
_X=0.000000
_Y=0.000000
_Z=0.000000
_DIVERGENCE=3.000000
_ANTISCATTER=3.000000
_DETECTOR=1
; S.C.
_HV=687.000000
_GAIN=80.000000
_LLD=0.690000
_ULD=1.866000
_DETECTORSLIT='unkn'
_AUX1=0.000000
_AUX2=0.000000
_AUX3=0.000000
_TIMESTARTED=23481.000000
_TEMP_RATE=0.000000
_TEMP_DELAY=0.000000
_KV=35
_MA=40
_RANGE_WL=1.788970
_3DPLANE=0
_2THETACPS
   0.0000    2202.5
; (Data for Range number 261)
_DRIVE='PHI'
_STEPTIME=10.000000
_STEPSIZE=5.000000
_STEPMODE='S'
_START=0.000000
_THETA=59.000000
_2THETA=118.000000
_KHI=25.000000
_PHI=0.000000
_X=0.000000
_Y=0.000000
_Z=0.000000
_DIVERGENCE=3.000000
_ANTISCATTER=3.000000
_DETECTOR=1
; S.C.
_HV=687.000000
_GAIN=80.000000
_LLD=0.690000
_ULD=1.866000
_DETECTORSLIT='unkn'
_AUX1=0.000000
_AUX2=0.000000
_AUX3=0.000000
_TIMESTARTED=23497.000000
_TEMP_RATE=0.000000
_TEMP_DELAY=0.000000
_KV=35
_MA=40
_RANGE_WL=1.788970
_3DPLANE=0
_2THETACPS
   0.0000    2247.6
; (Data for Range number 262)
_DRIVE='PHI'
_STEPTIME=10.000000
_STEPSIZE=5.000000
_STEPMODE='S'
_START=0.000000
_THETA=59.000000
_2THETA=118.000000
_KHI=30.000000
_PHI=0.000000
_X=0.000000
_Y=0.000000
_Z=0.000000
_DIVERGENCE=3.000000
_ANTISCATTER=3.000000
_DETECTOR=1
; S.C.
_HV=687.000000
_GAIN=80.000000
_LLD=0.690000
_ULD=1.866000
_DETECTORSLIT='unkn'
_AUX1=0.000000
_AUX2=0.000000
_AUX3=0.000000
_TIMESTARTED=23512.000000
_TEMP_RATE=0.000000
_TEMP_DELAY=0.000000
_KV=35
_MA=40
_RANGE_WL=1.788970
_3DPLANE=0
_2THETACPS
   0.0000    2270.4
; (Data for Range number 263)
_DRIVE='PHI'
_STEPTIME=10.000000
_STEPSIZE=5.000000
_STEPMODE='S'
_START=0.000000
_THETA=59.000000
_2THETA=118.000000
_KHI=35.000000
_PHI=0.000000
_X=0.000000
_Y=0.000000
_Z=0.000000
_DIVERGENCE=3.000000
_ANTISCATTER=3.000000
_DETECTOR=1
; S.C.
_HV=687.000000
_GAIN=80.000000
_LLD=0.690000
_ULD=1.866000
_DETECTORSLIT='unkn'
_AUX1=0.000000
_AUX2=0.000000
_AUX3=0.000000
_TIMESTARTED=23526.000000
_TEMP_RATE=0.000000
_TEMP_DELAY=0.000000
_KV=35
_MA=40
_RANGE_WL=1.788970
_3DPLANE=0
_2THETACPS
   0.0000    2247.1
; (Data for Range number 264)
_DRIVE='PHI'
_STEPTIME=10.000000
_STEPSIZE=5.000000
_STEPMODE='S'
_START=0.000000
_THETA=59.000000
_2THETA=118.000000
_KHI=40.000000
_PHI=0.000000
_X=0.000000
_Y=0.000000
_Z=0.000000
_DIVERGENCE=3.000000
_ANTISCATTER=3.000000
_DETECTOR=1
; S.C.
_HV=687.000000
_GAIN=80.000000
_LLD=0.690000
_ULD=1.866000
_DETECTORSLIT='unkn'
_AUX1=0.000000
_AUX2=0.000000
_AUX3=0.000000
_TIMESTARTED=23542.000000
_TEMP_RATE=0.000000
_TEMP_DELAY=0.000000
_KV=35
_MA=40
_RANGE_WL=1.788970
_3DPLANE=0
_2THETACPS
   0.0000    2226.9
; (Data for Range number 265)
_DRIVE='PHI'
_STEPTIME=10.000000
_STEPSIZE=5.000000
_STEPMODE='S'
_START=0.000000
_THETA=59.000000
_2THETA=118.000000
_KHI=45.000000
_PHI=0.000000
_X=0.000000
_Y=0.000000
_Z=0.000000
_DIVERGENCE=3.000000
_ANTISCATTER=3.000000
_DETECTOR=1
; S.C.
_HV=687.000000
_GAIN=80.000000
_LLD=0.690000
_ULD=1.866000
_DETECTORSLIT='unkn'
_AUX1=0.000000
_AUX2=0.000000
_AUX3=0.000000
_TIMESTARTED=23557.000000
_TEMP_RATE=0.000000
_TEMP_DELAY=0.000000
_KV=35
_MA=40
_RANGE_WL=1.788970
_3DPLANE=0
_2THETACPS
   0.0000    2214.2
; (Data for Range number 266)
_DRIVE='PHI'
_STEPTIME=10.000000
_STEPSIZE=5.000000
_STEPMODE='S'
_START=0.000000
_THETA=59.000000
_2THETA=118.000000
_KHI=50.000000
_PHI=0.000000
_X=0.000000
_Y=0.000000
_Z=0.000000
_DIVERGENCE=3.000000
_ANTISCATTER=3.000000
_DETECTOR=1
; S.C.
_HV=687.000000
_GAIN=80.000000
_LLD=0.690000
_ULD=1.866000
_DETECTORSLIT='unkn'
_AUX1=0.000000
_AUX2=0.000000
_AUX3=0.000000
_TIMESTARTED=23572.000000
_TEMP_RATE=0.000000
_TEMP_DELAY=0.000000
_KV=35
_MA=40
_RANGE_WL=1.788970
_3DPLANE=0
_2THETACPS
   0.0000    2218.1
; (Data for Range number 267)
_DRIVE='PHI'
_STEPTIME=10.000000
_STEPSIZE=5.000000
_STEPMODE='S'
_START=0.000000
_THETA=59.000000
_2THETA=118.000000
_KHI=55.000000
_PHI=0.000000
_X=0.000000
_Y=0.000000
_Z=0.000000
_DIVERGENCE=3.000000
_ANTISCATTER=3.000000
_DETECTOR=1
; S.C.
_HV=687.000000
_GAIN=80.000000
_LLD=0.690000
_ULD=1.866000
_DETECTORSLIT='unkn'
_AUX1=0.000000
_AUX2=0.000000
_AUX3=0.000000
_TIMESTARTED=23587.000000
_TEMP_RATE=0.000000
_TEMP_DELAY=0.000000
_KV=35
_MA=40
_RANGE_WL=1.788970
_3DPLANE=0
_2THETACPS
   0.0000    2206.4
; (Data for Range number 268)
_DRIVE='PHI'
_STEPTIME=10.000000
_STEPSIZE=5.000000
_STEPMODE='S'
_START=0.000000
_THETA=59.000000
_2THETA=118.000000
_KHI=60.000000
_PHI=0.000000
_X=0.000000
_Y=0.000000
_Z=0.000000
_DIVERGENCE=3.000000
_ANTISCATTER=3.000000
_DETECTOR=1
; S.C.
_HV=687.000000
_GAIN=80.000000
_LLD=0.690000
_ULD=1.866000
_DETECTORSLIT='unkn'
_AUX1=0.000000
_AUX2=0.000000
_AUX3=0.000000
_TIMESTARTED=23603.000000
_TEMP_RATE=0.000000
_TEMP_DELAY=0.000000
_KV=35
_MA=40
_RANGE_WL=1.788970
_3DPLANE=0
_2THETACPS
   0.0000    2183.5
; (Data for Range number 269)
_DRIVE='PHI'
_STEPTIME=10.000000
_STEPSIZE=5.000000
_STEPMODE='S'
_START=0.000000
_THETA=59.000000
_2THETA=118.000000
_KHI=65.000000
_PHI=0.000000
_X=0.000000
_Y=0.000000
_Z=0.000000
_DIVERGENCE=3.000000
_ANTISCATTER=3.000000
_DETECTOR=1
; S.C.
_HV=687.000000
_GAIN=80.000000
_LLD=0.690000
_ULD=1.866000
_DETECTORSLIT='unkn'
_AUX1=0.000000
_AUX2=0.000000
_AUX3=0.000000
_TIMESTARTED=23618.000000
_TEMP_RATE=0.000000
_TEMP_DELAY=0.000000
_KV=35
_MA=40
_RANGE_WL=1.788970
_3DPLANE=0
_2THETACPS
   0.0000    2198.3
; (Data for Range number 270)
_DRIVE='PHI'
_STEPTIME=10.000000
_STEPSIZE=5.000000
_STEPMODE='S'
_START=0.000000
_THETA=59.000000
_2THETA=118.000000
_KHI=70.000000
_PHI=0.000000
_X=0.000000
_Y=0.000000
_Z=0.000000
_DIVERGENCE=3.000000
_ANTISCATTER=3.000000
_DETECTOR=1
; S.C.
_HV=687.000000
_GAIN=80.000000
_LLD=0.690000
_ULD=1.866000
_DETECTORSLIT='unkn'
_AUX1=0.000000
_AUX2=0.000000
_AUX3=0.000000
_TIMESTARTED=23633.000000
_TEMP_RATE=0.000000
_TEMP_DELAY=0.000000
_KV=35
_MA=40
_RANGE_WL=1.788970
_3DPLANE=0
_2THETACPS
   0.0000    2174.8
; (Data for Range number 271)
_DRIVE='PHI'
_STEPTIME=10.000000
_STEPSIZE=5.000000
_STEPMODE='S'
_START=0.000000
_THETA=59.000000
_2THETA=118.000000
_KHI=75.000000
_PHI=0.000000
_X=0.000000
_Y=0.000000
_Z=0.000000
_DIVERGENCE=3.000000
_ANTISCATTER=3.000000
_DETECTOR=1
; S.C.
_HV=687.000000
_GAIN=80.000000
_LLD=0.690000
_ULD=1.866000
_DETECTORSLIT='unkn'
_AUX1=0.000000
_AUX2=0.000000
_AUX3=0.000000
_TIMESTARTED=23648.000000
_TEMP_RATE=0.000000
_TEMP_DELAY=0.000000
_KV=35
_MA=40
_RANGE_WL=1.788970
_3DPLANE=0
_2THETACPS
   0.0000    2074.5
; (Data for Range number 272)
_DRIVE='PHI'
_STEPTIME=10.000000
_STEPSIZE=5.000000
_STEPMODE='S'
_START=0.000000
_THETA=59.000000
_2THETA=118.000000
_KHI=80.000000
_PHI=0.000000
_X=0.000000
_Y=0.000000
_Z=0.000000
_DIVERGENCE=3.000000
_ANTISCATTER=3.000000
_DETECTOR=1
; S.C.
_HV=687.000000
_GAIN=80.000000
_LLD=0.690000
_ULD=1.866000
_DETECTORSLIT='unkn'
_AUX1=0.000000
_AUX2=0.000000
_AUX3=0.000000
_TIMESTARTED=23664.000000
_TEMP_RATE=0.000000
_TEMP_DELAY=0.000000
_KV=35
_MA=40
_RANGE_WL=1.788970
_3DPLANE=0
_2THETACPS
   0.0000    1707.5
; (Data for Range number 273)
_DRIVE='PHI'
_STEPTIME=10.000000
_STEPSIZE=5.000000
_STEPMODE='S'
_START=0.000000
_THETA=64.000000
_2THETA=128.000000
_KHI=0.000000
_PHI=0.000000
_X=0.000000
_Y=0.000000
_Z=0.000000
_DIVERGENCE=3.000000
_ANTISCATTER=3.000000
_DETECTOR=1
; S.C.
_HV=687.000000
_GAIN=80.000000
_LLD=0.690000
_ULD=1.866000
_DETECTORSLIT='unkn'
_AUX1=0.000000
_AUX2=0.000000
_AUX3=0.000000
_TIMESTARTED=23702.000000
_TEMP_RATE=0.000000
_TEMP_DELAY=0.000000
_KV=35
_MA=40
_RANGE_WL=1.788970
_3DPLANE=0
_2THETACPS
   0.0000    2177.4
; (Data for Range number 274)
_DRIVE='PHI'
_STEPTIME=10.000000
_STEPSIZE=5.000000
_STEPMODE='S'
_START=0.000000
_THETA=64.000000
_2THETA=128.000000
_KHI=5.000000
_PHI=0.000000
_X=0.000000
_Y=0.000000
_Z=0.000000
_DIVERGENCE=3.000000
_ANTISCATTER=3.000000
_DETECTOR=1
; S.C.
_HV=687.000000
_GAIN=80.000000
_LLD=0.690000
_ULD=1.866000
_DETECTORSLIT='unkn'
_AUX1=0.000000
_AUX2=0.000000
_AUX3=0.000000
_TIMESTARTED=23717.000000
_TEMP_RATE=0.000000
_TEMP_DELAY=0.000000
_KV=35
_MA=40
_RANGE_WL=1.788970
_3DPLANE=0
_2THETACPS
   0.0000    2216.3
; (Data for Range number 275)
_DRIVE='PHI'
_STEPTIME=10.000000
_STEPSIZE=5.000000
_STEPMODE='S'
_START=0.000000
_THETA=64.000000
_2THETA=128.000000
_KHI=10.000000
_PHI=0.000000
_X=0.000000
_Y=0.000000
_Z=0.000000
_DIVERGENCE=3.000000
_ANTISCATTER=3.000000
_DETECTOR=1
; S.C.
_HV=687.000000
_GAIN=80.000000
_LLD=0.690000
_ULD=1.866000
_DETECTORSLIT='unkn'
_AUX1=0.000000
_AUX2=0.000000
_AUX3=0.000000
_TIMESTARTED=23732.000000
_TEMP_RATE=0.000000
_TEMP_DELAY=0.000000
_KV=35
_MA=40
_RANGE_WL=1.788970
_3DPLANE=0
_2THETACPS
   0.0000    2204.5
; (Data for Range number 276)
_DRIVE='PHI'
_STEPTIME=10.000000
_STEPSIZE=5.000000
_STEPMODE='S'
_START=0.000000
_THETA=64.000000
_2THETA=128.000000
_KHI=15.000000
_PHI=0.000000
_X=0.000000
_Y=0.000000
_Z=0.000000
_DIVERGENCE=3.000000
_ANTISCATTER=3.000000
_DETECTOR=1
; S.C.
_HV=687.000000
_GAIN=80.000000
_LLD=0.690000
_ULD=1.866000
_DETECTORSLIT='unkn'
_AUX1=0.000000
_AUX2=0.000000
_AUX3=0.000000
_TIMESTARTED=23747.000000
_TEMP_RATE=0.000000
_TEMP_DELAY=0.000000
_KV=35
_MA=40
_RANGE_WL=1.788970
_3DPLANE=0
_2THETACPS
   0.0000    2194.0
; (Data for Range number 277)
_DRIVE='PHI'
_STEPTIME=10.000000
_STEPSIZE=5.000000
_STEPMODE='S'
_START=0.000000
_THETA=64.000000
_2THETA=128.000000
_KHI=20.000000
_PHI=0.000000
_X=0.000000
_Y=0.000000
_Z=0.000000
_DIVERGENCE=3.000000
_ANTISCATTER=3.000000
_DETECTOR=1
; S.C.
_HV=687.000000
_GAIN=80.000000
_LLD=0.690000
_ULD=1.866000
_DETECTORSLIT='unkn'
_AUX1=0.000000
_AUX2=0.000000
_AUX3=0.000000
_TIMESTARTED=23762.000000
_TEMP_RATE=0.000000
_TEMP_DELAY=0.000000
_KV=35
_MA=40
_RANGE_WL=1.788970
_3DPLANE=0
_2THETACPS
   0.0000    2219.2
; (Data for Range number 278)
_DRIVE='PHI'
_STEPTIME=10.000000
_STEPSIZE=5.000000
_STEPMODE='S'
_START=0.000000
_THETA=64.000000
_2THETA=128.000000
_KHI=25.000000
_PHI=0.000000
_X=0.000000
_Y=0.000000
_Z=0.000000
_DIVERGENCE=3.000000
_ANTISCATTER=3.000000
_DETECTOR=1
; S.C.
_HV=687.000000
_GAIN=80.000000
_LLD=0.690000
_ULD=1.866000
_DETECTORSLIT='unkn'
_AUX1=0.000000
_AUX2=0.000000
_AUX3=0.000000
_TIMESTARTED=23778.000000
_TEMP_RATE=0.000000
_TEMP_DELAY=0.000000
_KV=35
_MA=40
_RANGE_WL=1.788970
_3DPLANE=0
_2THETACPS
   0.0000    2225.4
; (Data for Range number 279)
_DRIVE='PHI'
_STEPTIME=10.000000
_STEPSIZE=5.000000
_STEPMODE='S'
_START=0.000000
_THETA=64.000000
_2THETA=128.000000
_KHI=30.000000
_PHI=0.000000
_X=0.000000
_Y=0.000000
_Z=0.000000
_DIVERGENCE=3.000000
_ANTISCATTER=3.000000
_DETECTOR=1
; S.C.
_HV=687.000000
_GAIN=80.000000
_LLD=0.690000
_ULD=1.866000
_DETECTORSLIT='unkn'
_AUX1=0.000000
_AUX2=0.000000
_AUX3=0.000000
_TIMESTARTED=23792.000000
_TEMP_RATE=0.000000
_TEMP_DELAY=0.000000
_KV=35
_MA=40
_RANGE_WL=1.788970
_3DPLANE=0
_2THETACPS
   0.0000    2220.8
; (Data for Range number 280)
_DRIVE='PHI'
_STEPTIME=10.000000
_STEPSIZE=5.000000
_STEPMODE='S'
_START=0.000000
_THETA=64.000000
_2THETA=128.000000
_KHI=35.000000
_PHI=0.000000
_X=0.000000
_Y=0.000000
_Z=0.000000
_DIVERGENCE=3.000000
_ANTISCATTER=3.000000
_DETECTOR=1
; S.C.
_HV=687.000000
_GAIN=80.000000
_LLD=0.690000
_ULD=1.866000
_DETECTORSLIT='unkn'
_AUX1=0.000000
_AUX2=0.000000
_AUX3=0.000000
_TIMESTARTED=23807.000000
_TEMP_RATE=0.000000
_TEMP_DELAY=0.000000
_KV=35
_MA=40
_RANGE_WL=1.788970
_3DPLANE=0
_2THETACPS
   0.0000    2221.5
; (Data for Range number 281)
_DRIVE='PHI'
_STEPTIME=10.000000
_STEPSIZE=5.000000
_STEPMODE='S'
_START=0.000000
_THETA=64.000000
_2THETA=128.000000
_KHI=40.000000
_PHI=0.000000
_X=0.000000
_Y=0.000000
_Z=0.000000
_DIVERGENCE=3.000000
_ANTISCATTER=3.000000
_DETECTOR=1
; S.C.
_HV=687.000000
_GAIN=80.000000
_LLD=0.690000
_ULD=1.866000
_DETECTORSLIT='unkn'
_AUX1=0.000000
_AUX2=0.000000
_AUX3=0.000000
_TIMESTARTED=23822.000000
_TEMP_RATE=0.000000
_TEMP_DELAY=0.000000
_KV=35
_MA=40
_RANGE_WL=1.788970
_3DPLANE=0
_2THETACPS
   0.0000    2205.1
; (Data for Range number 282)
_DRIVE='PHI'
_STEPTIME=10.000000
_STEPSIZE=5.000000
_STEPMODE='S'
_START=0.000000
_THETA=64.000000
_2THETA=128.000000
_KHI=45.000000
_PHI=0.000000
_X=0.000000
_Y=0.000000
_Z=0.000000
_DIVERGENCE=3.000000
_ANTISCATTER=3.000000
_DETECTOR=1
; S.C.
_HV=687.000000
_GAIN=80.000000
_LLD=0.690000
_ULD=1.866000
_DETECTORSLIT='unkn'
_AUX1=0.000000
_AUX2=0.000000
_AUX3=0.000000
_TIMESTARTED=23838.000000
_TEMP_RATE=0.000000
_TEMP_DELAY=0.000000
_KV=35
_MA=40
_RANGE_WL=1.788970
_3DPLANE=0
_2THETACPS
   0.0000    2208.9
; (Data for Range number 283)
_DRIVE='PHI'
_STEPTIME=10.000000
_STEPSIZE=5.000000
_STEPMODE='S'
_START=0.000000
_THETA=64.000000
_2THETA=128.000000
_KHI=50.000000
_PHI=0.000000
_X=0.000000
_Y=0.000000
_Z=0.000000
_DIVERGENCE=3.000000
_ANTISCATTER=3.000000
_DETECTOR=1
; S.C.
_HV=687.000000
_GAIN=80.000000
_LLD=0.690000
_ULD=1.866000
_DETECTORSLIT='unkn'
_AUX1=0.000000
_AUX2=0.000000
_AUX3=0.000000
_TIMESTARTED=23853.000000
_TEMP_RATE=0.000000
_TEMP_DELAY=0.000000
_KV=35
_MA=40
_RANGE_WL=1.788970
_3DPLANE=0
_2THETACPS
   0.0000    2183.0
; (Data for Range number 284)
_DRIVE='PHI'
_STEPTIME=10.000000
_STEPSIZE=5.000000
_STEPMODE='S'
_START=0.000000
_THETA=64.000000
_2THETA=128.000000
_KHI=55.000000
_PHI=0.000000
_X=0.000000
_Y=0.000000
_Z=0.000000
_DIVERGENCE=3.000000
_ANTISCATTER=3.000000
_DETECTOR=1
; S.C.
_HV=687.000000
_GAIN=80.000000
_LLD=0.690000
_ULD=1.866000
_DETECTORSLIT='unkn'
_AUX1=0.000000
_AUX2=0.000000
_AUX3=0.000000
_TIMESTARTED=23867.000000
_TEMP_RATE=0.000000
_TEMP_DELAY=0.000000
_KV=35
_MA=40
_RANGE_WL=1.788970
_3DPLANE=0
_2THETACPS
   0.0000    2227.1
; (Data for Range number 285)
_DRIVE='PHI'
_STEPTIME=10.000000
_STEPSIZE=5.000000
_STEPMODE='S'
_START=0.000000
_THETA=64.000000
_2THETA=128.000000
_KHI=60.000000
_PHI=0.000000
_X=0.000000
_Y=0.000000
_Z=0.000000
_DIVERGENCE=3.000000
_ANTISCATTER=3.000000
_DETECTOR=1
; S.C.
_HV=687.000000
_GAIN=80.000000
_LLD=0.690000
_ULD=1.866000
_DETECTORSLIT='unkn'
_AUX1=0.000000
_AUX2=0.000000
_AUX3=0.000000
_TIMESTARTED=23883.000000
_TEMP_RATE=0.000000
_TEMP_DELAY=0.000000
_KV=35
_MA=40
_RANGE_WL=1.788970
_3DPLANE=0
_2THETACPS
   0.0000    2184.7
; (Data for Range number 286)
_DRIVE='PHI'
_STEPTIME=10.000000
_STEPSIZE=5.000000
_STEPMODE='S'
_START=0.000000
_THETA=64.000000
_2THETA=128.000000
_KHI=65.000000
_PHI=0.000000
_X=0.000000
_Y=0.000000
_Z=0.000000
_DIVERGENCE=3.000000
_ANTISCATTER=3.000000
_DETECTOR=1
; S.C.
_HV=687.000000
_GAIN=80.000000
_LLD=0.690000
_ULD=1.866000
_DETECTORSLIT='unkn'
_AUX1=0.000000
_AUX2=0.000000
_AUX3=0.000000
_TIMESTARTED=23898.000000
_TEMP_RATE=0.000000
_TEMP_DELAY=0.000000
_KV=35
_MA=40
_RANGE_WL=1.788970
_3DPLANE=0
_2THETACPS
   0.0000    2200.4
; (Data for Range number 287)
_DRIVE='PHI'
_STEPTIME=10.000000
_STEPSIZE=5.000000
_STEPMODE='S'
_START=0.000000
_THETA=64.000000
_2THETA=128.000000
_KHI=70.000000
_PHI=0.000000
_X=0.000000
_Y=0.000000
_Z=0.000000
_DIVERGENCE=3.000000
_ANTISCATTER=3.000000
_DETECTOR=1
; S.C.
_HV=687.000000
_GAIN=80.000000
_LLD=0.690000
_ULD=1.866000
_DETECTORSLIT='unkn'
_AUX1=0.000000
_AUX2=0.000000
_AUX3=0.000000
_TIMESTARTED=23912.000000
_TEMP_RATE=0.000000
_TEMP_DELAY=0.000000
_KV=35
_MA=40
_RANGE_WL=1.788970
_3DPLANE=0
_2THETACPS
   0.0000    2187.5
; (Data for Range number 288)
_DRIVE='PHI'
_STEPTIME=10.000000
_STEPSIZE=5.000000
_STEPMODE='S'
_START=0.000000
_THETA=64.000000
_2THETA=128.000000
_KHI=75.000000
_PHI=0.000000
_X=0.000000
_Y=0.000000
_Z=0.000000
_DIVERGENCE=3.000000
_ANTISCATTER=3.000000
_DETECTOR=1
; S.C.
_HV=687.000000
_GAIN=80.000000
_LLD=0.690000
_ULD=1.866000
_DETECTORSLIT='unkn'
_AUX1=0.000000
_AUX2=0.000000
_AUX3=0.000000
_TIMESTARTED=23928.000000
_TEMP_RATE=0.000000
_TEMP_DELAY=0.000000
_KV=35
_MA=40
_RANGE_WL=1.788970
_3DPLANE=0
_2THETACPS
   0.0000    2180.7
; (Data for Range number 289)
_DRIVE='PHI'
_STEPTIME=10.000000
_STEPSIZE=5.000000
_STEPMODE='S'
_START=0.000000
_THETA=64.000000
_2THETA=128.000000
_KHI=80.000000
_PHI=0.000000
_X=0.000000
_Y=0.000000
_Z=0.000000
_DIVERGENCE=3.000000
_ANTISCATTER=3.000000
_DETECTOR=1
; S.C.
_HV=687.000000
_GAIN=80.000000
_LLD=0.690000
_ULD=1.866000
_DETECTORSLIT='unkn'
_AUX1=0.000000
_AUX2=0.000000
_AUX3=0.000000
_TIMESTARTED=23942.000000
_TEMP_RATE=0.000000
_TEMP_DELAY=0.000000
_KV=35
_MA=40
_RANGE_WL=1.788970
_3DPLANE=0
_2THETACPS
   0.0000    1917.6